[2025-10-24T01:10:23.435+0000] {taskinstance.py:1956} INFO - Dependencies all met for dep_context=non-requeueable deps ti=<TaskInstance: etl_pipeline_scd2.run_processor_harmonizer manual__2025-10-24T01:08:43.658329+00:00 [queued]>
[2025-10-24T01:10:23.466+0000] {taskinstance.py:1956} INFO - Dependencies all met for dep_context=requeueable deps ti=<TaskInstance: etl_pipeline_scd2.run_processor_harmonizer manual__2025-10-24T01:08:43.658329+00:00 [queued]>
[2025-10-24T01:10:23.467+0000] {taskinstance.py:2170} INFO - Starting attempt 1 of 1
[2025-10-24T01:10:23.523+0000] {taskinstance.py:2191} INFO - Executing <Task(PythonOperator): run_processor_harmonizer> on 2025-10-24 01:08:43.658329+00:00
[2025-10-24T01:10:23.633+0000] {standard_task_runner.py:60} INFO - Started process 4342 to run task
[2025-10-24T01:10:23.660+0000] {standard_task_runner.py:87} INFO - Running: ['***', 'tasks', 'run', 'etl_pipeline_scd2', 'run_processor_harmonizer', 'manual__2025-10-24T01:08:43.658329+00:00', '--job-id', '217', '--raw', '--subdir', 'DAGS_FOLDER/process_scripts.py', '--cfg-path', '/tmp/tmp9npj67_d']
[2025-10-24T01:10:23.689+0000] {standard_task_runner.py:88} INFO - Job 217: Subtask run_processor_harmonizer
[2025-10-24T01:10:23.818+0000] {logging_mixin.py:188} WARNING - /home/***/.local/lib/python3.11/site-packages/***/settings.py:194 DeprecationWarning: The sql_alchemy_conn option in [core] has been moved to the sql_alchemy_conn option in [database] - the old setting has been used, but please update your config.
[2025-10-24T01:10:24.139+0000] {task_command.py:423} INFO - Running <TaskInstance: etl_pipeline_scd2.run_processor_harmonizer manual__2025-10-24T01:08:43.658329+00:00 [running]> on host ca755dafa923
[2025-10-24T01:10:24.436+0000] {taskinstance.py:2480} INFO - Exporting env vars: AIRFLOW_CTX_DAG_OWNER='***' AIRFLOW_CTX_DAG_ID='etl_pipeline_scd2' AIRFLOW_CTX_TASK_ID='run_processor_harmonizer' AIRFLOW_CTX_EXECUTION_DATE='2025-10-24T01:08:43.658329+00:00' AIRFLOW_CTX_TRY_NUMBER='1' AIRFLOW_CTX_DAG_RUN_ID='manual__2025-10-24T01:08:43.658329+00:00'
[2025-10-24T01:10:24.439+0000] {logging_mixin.py:188} INFO - Exécution du script : /opt/***/scripts/processor_harmonizer.py
[2025-10-24T01:12:32.652+0000] {taskinstance.py:2698} ERROR - Task failed with exception
Traceback (most recent call last):
  File "/home/airflow/.local/lib/python3.11/site-packages/airflow/models/taskinstance.py", line 433, in _execute_task
    result = execute_callable(context=context, **execute_callable_kwargs)
             ^^^^^^^^^^^^^^^^^^^^^^^^^^^^^^^^^^^^^^^^^^^^^^^^^^^^^^^^^^^^
  File "/home/airflow/.local/lib/python3.11/site-packages/airflow/operators/python.py", line 199, in execute
    return_value = self.execute_callable()
                   ^^^^^^^^^^^^^^^^^^^^^^^
  File "/home/airflow/.local/lib/python3.11/site-packages/airflow/operators/python.py", line 216, in execute_callable
    return self.python_callable(*self.op_args, **self.op_kwargs)
           ^^^^^^^^^^^^^^^^^^^^^^^^^^^^^^^^^^^^^^^^^^^^^^^^^^^^^
  File "/opt/airflow/dags/process_scripts.py", line 43, in run_script
    raise Exception(
Exception: Script /opt/***/scripts/processor_harmonizer.py failed
STDOUT:
1227/5160 lignes mises à jour, 2977 lignes ignorées dans Extract_Station_20251024.xlsx (logs → data/out/Harmonize log/20251024T011042Z)

STDERR:
Traceback (most recent call last):
  File "/opt/***/scripts/processor_harmonizer.py", line 292, in <module>
    update_all_in_out(score_threshold=50, code_pad_width=0)
  File "/opt/***/scripts/processor_harmonizer.py", line 286, in update_all_in_out
    update_file_batch(ref, file_path, updated_dir, backup_dir, log_root,
  File "/opt/***/scripts/processor_harmonizer.py", line 238, in update_file_batch
    shutil.copy2(file_path, bak_path)
  File "/usr/local/lib/python3.11/shutil.py", line 448, in copy2
    copyfile(src, dst, follow_symlinks=follow_symlinks)
  File "/usr/local/lib/python3.11/shutil.py", line 256, in copyfile
    with open(src, 'rb') as fsrc:
         ^^^^^^^^^^^^^^^
FileNotFoundError: [Errno 2] No such file or directory: 'data/out/Invariants_details_20251024.xlsx'

[2025-10-24T01:12:33.261+0000] {taskinstance.py:1138} INFO - Marking task as FAILED. dag_id=etl_pipeline_scd2, task_id=run_processor_harmonizer, execution_date=20251024T010843, start_date=20251024T011023, end_date=20251024T011233
[2025-10-24T01:12:33.464+0000] {standard_task_runner.py:107} ERROR - Failed to execute job 217 for task run_processor_harmonizer (Script /opt/***/scripts/processor_harmonizer.py failed
STDOUT:
1227/5160 lignes mises à jour, 2977 lignes ignorées dans Extract_Station_20251024.xlsx (logs → data/out/Harmonize log/20251024T011042Z)

STDERR:
Traceback (most recent call last):
  File "/opt/***/scripts/processor_harmonizer.py", line 292, in <module>
    update_all_in_out(score_threshold=50, code_pad_width=0)
  File "/opt/***/scripts/processor_harmonizer.py", line 286, in update_all_in_out
    update_file_batch(ref, file_path, updated_dir, backup_dir, log_root,
  File "/opt/***/scripts/processor_harmonizer.py", line 238, in update_file_batch
    shutil.copy2(file_path, bak_path)
  File "/usr/local/lib/python3.11/shutil.py", line 448, in copy2
    copyfile(src, dst, follow_symlinks=follow_symlinks)
  File "/usr/local/lib/python3.11/shutil.py", line 256, in copyfile
    with open(src, 'rb') as fsrc:
         ^^^^^^^^^^^^^^^
FileNotFoundError: [Errno 2] No such file or directory: 'data/out/Invariants_details_20251024.xlsx'
; 4342)
[2025-10-24T01:12:33.585+0000] {local_task_job_runner.py:234} INFO - Task exited with return code 1
[2025-10-24T01:12:33.832+0000] {taskinstance.py:3280} INFO - 0 downstream tasks scheduled from follow-on schedule check
