[2025-10-04T14:55:39.671+0000] {taskinstance.py:1956} INFO - Dependencies all met for dep_context=non-requeueable deps ti=<TaskInstance: etl_pipeline_scd2.load_to_dw_scd2 manual__2025-10-04T14:53:38.718464+00:00 [queued]>
[2025-10-04T14:55:39.705+0000] {taskinstance.py:1956} INFO - Dependencies all met for dep_context=requeueable deps ti=<TaskInstance: etl_pipeline_scd2.load_to_dw_scd2 manual__2025-10-04T14:53:38.718464+00:00 [queued]>
[2025-10-04T14:55:39.708+0000] {taskinstance.py:2170} INFO - Starting attempt 1 of 1
[2025-10-04T14:55:39.769+0000] {taskinstance.py:2191} INFO - Executing <Task(PythonOperator): load_to_dw_scd2> on 2025-10-04 14:53:38.718464+00:00
[2025-10-04T14:55:39.797+0000] {standard_task_runner.py:60} INFO - Started process 652 to run task
[2025-10-04T14:55:39.827+0000] {standard_task_runner.py:87} INFO - Running: ['***', 'tasks', 'run', 'etl_pipeline_scd2', 'load_to_dw_scd2', 'manual__2025-10-04T14:53:38.718464+00:00', '--job-id', '103', '--raw', '--subdir', 'DAGS_FOLDER/process_scripts.py', '--cfg-path', '/tmp/tmpey4q78vv']
[2025-10-04T14:55:39.846+0000] {standard_task_runner.py:88} INFO - Job 103: Subtask load_to_dw_scd2
[2025-10-04T14:55:39.975+0000] {logging_mixin.py:188} WARNING - /home/***/.local/lib/python3.11/site-packages/***/settings.py:194 DeprecationWarning: The sql_alchemy_conn option in [core] has been moved to the sql_alchemy_conn option in [database] - the old setting has been used, but please update your config.
[2025-10-04T14:55:40.172+0000] {task_command.py:423} INFO - Running <TaskInstance: etl_pipeline_scd2.load_to_dw_scd2 manual__2025-10-04T14:53:38.718464+00:00 [running]> on host 28712a281084
[2025-10-04T14:55:40.486+0000] {taskinstance.py:2480} INFO - Exporting env vars: AIRFLOW_CTX_DAG_OWNER='***' AIRFLOW_CTX_DAG_ID='etl_pipeline_scd2' AIRFLOW_CTX_TASK_ID='load_to_dw_scd2' AIRFLOW_CTX_EXECUTION_DATE='2025-10-04T14:53:38.718464+00:00' AIRFLOW_CTX_TRY_NUMBER='1' AIRFLOW_CTX_DAG_RUN_ID='manual__2025-10-04T14:53:38.718464+00:00'
[2025-10-04T14:55:42.201+0000] {scd2_loader.py:213} INFO - üìÇ Traitement du fichier: Country_code.xlsx
[2025-10-04T14:55:45.505+0000] {scd2_loader.py:255} WARNING - 1 lignes ignor√©es (cl√©s manquantes) dans Country_code.xlsx::0
[2025-10-04T14:55:45.686+0000] {scd2_loader.py:168} INFO - ‚ö†Ô∏è Doublon ignor√© pour dim_pays cl√©=('NG',)
[2025-10-04T14:55:45.687+0000] {scd2_loader.py:168} INFO - ‚ö†Ô∏è Doublon ignor√© pour dim_pays cl√©=('YT',)
[2025-10-04T14:55:45.689+0000] {scd2_loader.py:168} INFO - ‚ö†Ô∏è Doublon ignor√© pour dim_pays cl√©=('ER',)
[2025-10-04T14:55:45.691+0000] {scd2_loader.py:168} INFO - ‚ö†Ô∏è Doublon ignor√© pour dim_pays cl√©=('ET',)
[2025-10-04T14:55:45.694+0000] {scd2_loader.py:168} INFO - ‚ö†Ô∏è Doublon ignor√© pour dim_pays cl√©=('MG',)
[2025-10-04T14:55:45.696+0000] {scd2_loader.py:168} INFO - ‚ö†Ô∏è Doublon ignor√© pour dim_pays cl√©=('MA',)
[2025-10-04T14:55:45.698+0000] {scd2_loader.py:168} INFO - ‚ö†Ô∏è Doublon ignor√© pour dim_pays cl√©=('MU',)
[2025-10-04T14:55:45.701+0000] {scd2_loader.py:168} INFO - ‚ö†Ô∏è Doublon ignor√© pour dim_pays cl√©=('RE',)
[2025-10-04T14:55:45.702+0000] {scd2_loader.py:168} INFO - ‚ö†Ô∏è Doublon ignor√© pour dim_pays cl√©=('TN',)
[2025-10-04T14:55:45.704+0000] {scd2_loader.py:168} INFO - ‚ö†Ô∏è Doublon ignor√© pour dim_pays cl√©=('TG',)
[2025-10-04T14:55:45.705+0000] {scd2_loader.py:168} INFO - ‚ö†Ô∏è Doublon ignor√© pour dim_pays cl√©=('TD',)
[2025-10-04T14:55:45.707+0000] {scd2_loader.py:168} INFO - ‚ö†Ô∏è Doublon ignor√© pour dim_pays cl√©=('SN',)
[2025-10-04T14:55:45.710+0000] {scd2_loader.py:168} INFO - ‚ö†Ô∏è Doublon ignor√© pour dim_pays cl√©=('ML',)
[2025-10-04T14:55:45.711+0000] {scd2_loader.py:168} INFO - ‚ö†Ô∏è Doublon ignor√© pour dim_pays cl√©=('GH',)
[2025-10-04T14:55:45.713+0000] {scd2_loader.py:168} INFO - ‚ö†Ô∏è Doublon ignor√© pour dim_pays cl√©=('GN',)
[2025-10-04T14:55:45.714+0000] {scd2_loader.py:168} INFO - ‚ö†Ô∏è Doublon ignor√© pour dim_pays cl√©=('BW',)
[2025-10-04T14:55:45.715+0000] {scd2_loader.py:168} INFO - ‚ö†Ô∏è Doublon ignor√© pour dim_pays cl√©=('ZA',)
[2025-10-04T14:55:45.716+0000] {scd2_loader.py:168} INFO - ‚ö†Ô∏è Doublon ignor√© pour dim_pays cl√©=('SZ',)
[2025-10-04T14:55:45.718+0000] {scd2_loader.py:168} INFO - ‚ö†Ô∏è Doublon ignor√© pour dim_pays cl√©=('MW',)
[2025-10-04T14:55:45.719+0000] {scd2_loader.py:168} INFO - ‚ö†Ô∏è Doublon ignor√© pour dim_pays cl√©=('AO',)
[2025-10-04T14:55:45.720+0000] {scd2_loader.py:168} INFO - ‚ö†Ô∏è Doublon ignor√© pour dim_pays cl√©=('MZ',)
[2025-10-04T14:55:45.721+0000] {scd2_loader.py:168} INFO - ‚ö†Ô∏è Doublon ignor√© pour dim_pays cl√©=('ZW',)
[2025-10-04T14:55:45.724+0000] {scd2_loader.py:168} INFO - ‚ö†Ô∏è Doublon ignor√© pour dim_pays cl√©=('ZM',)
[2025-10-04T14:55:45.725+0000] {scd2_loader.py:168} INFO - ‚ö†Ô∏è Doublon ignor√© pour dim_pays cl√©=('CM',)
[2025-10-04T14:55:45.727+0000] {scd2_loader.py:168} INFO - ‚ö†Ô∏è Doublon ignor√© pour dim_pays cl√©=('CD',)
[2025-10-04T14:55:45.729+0000] {scd2_loader.py:168} INFO - ‚ö†Ô∏è Doublon ignor√© pour dim_pays cl√©=('GA',)
[2025-10-04T14:55:45.731+0000] {scd2_loader.py:168} INFO - ‚ö†Ô∏è Doublon ignor√© pour dim_pays cl√©=('KE',)
[2025-10-04T14:55:45.733+0000] {scd2_loader.py:168} INFO - ‚ö†Ô∏è Doublon ignor√© pour dim_pays cl√©=('UG',)
[2025-10-04T14:55:45.735+0000] {scd2_loader.py:168} INFO - ‚ö†Ô∏è Doublon ignor√© pour dim_pays cl√©=('TZ',)
[2025-10-04T14:55:45.736+0000] {scd2_loader.py:194} INFO - [SCD2] dim_pays ‚Üí inserts=0, updates_closed=0
[2025-10-04T14:55:45.737+0000] {scd2_loader.py:213} INFO - üìÇ Traitement du fichier: Extract_Station.xlsx
[2025-10-04T14:55:46.250+0000] {scd2_loader.py:255} WARNING - 569 lignes ignor√©es (cl√©s manquantes) dans Extract_Station.xlsx::0
[2025-10-04T14:55:46.607+0000] {taskinstance.py:2698} ERROR - Task failed with exception
Traceback (most recent call last):
  File "/home/airflow/.local/lib/python3.11/site-packages/sqlalchemy/engine/base.py", line 1890, in _execute_context
    self.dialect.do_executemany(
  File "/home/airflow/.local/lib/python3.11/site-packages/sqlalchemy/dialects/mysql/mysqldb.py", line 183, in do_executemany
    rowcount = cursor.executemany(statement, parameters)
               ^^^^^^^^^^^^^^^^^^^^^^^^^^^^^^^^^^^^^^^^^
  File "/home/airflow/.local/lib/python3.11/site-packages/MySQLdb/cursors.py", line 241, in executemany
    return self._do_execute_many(
           ^^^^^^^^^^^^^^^^^^^^^^
  File "/home/airflow/.local/lib/python3.11/site-packages/MySQLdb/cursors.py", line 275, in _do_execute_many
    rows += self.execute(sql + postfix)
            ^^^^^^^^^^^^^^^^^^^^^^^^^^^
  File "/home/airflow/.local/lib/python3.11/site-packages/MySQLdb/cursors.py", line 179, in execute
    res = self._query(mogrified_query)
          ^^^^^^^^^^^^^^^^^^^^^^^^^^^^
  File "/home/airflow/.local/lib/python3.11/site-packages/MySQLdb/cursors.py", line 330, in _query
    db.query(q)
  File "/home/airflow/.local/lib/python3.11/site-packages/MySQLdb/connections.py", line 257, in query
    _mysql.connection.query(self, query)
MySQLdb.OperationalError: (1054, "Unknown column 'station_name' in 'field list'")

The above exception was the direct cause of the following exception:

Traceback (most recent call last):
  File "/home/airflow/.local/lib/python3.11/site-packages/airflow/models/taskinstance.py", line 433, in _execute_task
    result = execute_callable(context=context, **execute_callable_kwargs)
             ^^^^^^^^^^^^^^^^^^^^^^^^^^^^^^^^^^^^^^^^^^^^^^^^^^^^^^^^^^^^
  File "/home/airflow/.local/lib/python3.11/site-packages/airflow/operators/python.py", line 199, in execute
    return_value = self.execute_callable()
                   ^^^^^^^^^^^^^^^^^^^^^^^
  File "/home/airflow/.local/lib/python3.11/site-packages/airflow/operators/python.py", line 216, in execute_callable
    return self.python_callable(*self.op_args, **self.op_kwargs)
           ^^^^^^^^^^^^^^^^^^^^^^^^^^^^^^^^^^^^^^^^^^^^^^^^^^^^^
  File "/opt/airflow/dags/process_scripts.py", line 28, in run_scd2_loader
    load_all_out_files_to_dw()
  File "/opt/airflow/dags/scd2_loader.py", line 257, in load_all_out_files_to_dw
    ins, upd = _process_table_batch(engine, table_name, df, business_keys, now)
               ^^^^^^^^^^^^^^^^^^^^^^^^^^^^^^^^^^^^^^^^^^^^^^^^^^^^^^^^^^^^^^^^
  File "/opt/airflow/dags/scd2_loader.py", line 190, in _process_table_batch
    conn.execute(insert_sql, chunk)
  File "/home/airflow/.local/lib/python3.11/site-packages/sqlalchemy/engine/base.py", line 1385, in execute
    return meth(self, multiparams, params, _EMPTY_EXECUTION_OPTS)
           ^^^^^^^^^^^^^^^^^^^^^^^^^^^^^^^^^^^^^^^^^^^^^^^^^^^^^^
  File "/home/airflow/.local/lib/python3.11/site-packages/sqlalchemy/sql/elements.py", line 334, in _execute_on_connection
    return connection._execute_clauseelement(
           ^^^^^^^^^^^^^^^^^^^^^^^^^^^^^^^^^^
  File "/home/airflow/.local/lib/python3.11/site-packages/sqlalchemy/engine/base.py", line 1577, in _execute_clauseelement
    ret = self._execute_context(
          ^^^^^^^^^^^^^^^^^^^^^^
  File "/home/airflow/.local/lib/python3.11/site-packages/sqlalchemy/engine/base.py", line 1953, in _execute_context
    self._handle_dbapi_exception(
  File "/home/airflow/.local/lib/python3.11/site-packages/sqlalchemy/engine/base.py", line 2134, in _handle_dbapi_exception
    util.raise_(
  File "/home/airflow/.local/lib/python3.11/site-packages/sqlalchemy/util/compat.py", line 211, in raise_
    raise exception
  File "/home/airflow/.local/lib/python3.11/site-packages/sqlalchemy/engine/base.py", line 1890, in _execute_context
    self.dialect.do_executemany(
  File "/home/airflow/.local/lib/python3.11/site-packages/sqlalchemy/dialects/mysql/mysqldb.py", line 183, in do_executemany
    rowcount = cursor.executemany(statement, parameters)
               ^^^^^^^^^^^^^^^^^^^^^^^^^^^^^^^^^^^^^^^^^
  File "/home/airflow/.local/lib/python3.11/site-packages/MySQLdb/cursors.py", line 241, in executemany
    return self._do_execute_many(
           ^^^^^^^^^^^^^^^^^^^^^^
  File "/home/airflow/.local/lib/python3.11/site-packages/MySQLdb/cursors.py", line 275, in _do_execute_many
    rows += self.execute(sql + postfix)
            ^^^^^^^^^^^^^^^^^^^^^^^^^^^
  File "/home/airflow/.local/lib/python3.11/site-packages/MySQLdb/cursors.py", line 179, in execute
    res = self._query(mogrified_query)
          ^^^^^^^^^^^^^^^^^^^^^^^^^^^^
  File "/home/airflow/.local/lib/python3.11/site-packages/MySQLdb/cursors.py", line 330, in _query
    db.query(q)
  File "/home/airflow/.local/lib/python3.11/site-packages/MySQLdb/connections.py", line 257, in query
    _mysql.connection.query(self, query)
sqlalchemy.exc.OperationalError: (MySQLdb.OperationalError) (1054, "Unknown column 'station_name' in 'field list'")
[SQL: INSERT INTO `dim_stations` (`cost_center`, `station_name`, `city`, `segmentation`, `management_method`, `code_du_pays`, `is_current`, `start_date`) VALUES (%s, %s, %s, %s, %s, %s, %s, %s)]
[parameters: (('NG111S0307', 'DOKA CRS SS', 'KADUNA', 'S1', 'CODO', 'NG', 1, datetime.datetime(2025, 10, 4, 14, 55, 42, 188546, tzinfo=datetime.timezone.utc)), ('NG111S0313', 'SOUTH BRIDGE', 'KADUNA', 'S1', 'CODO', 'NG', 1, datetime.datetime(2025, 10, 4, 14, 55, 42, 188546, tzinfo=datetime.timezone.utc)), ('NG111S0206', 'RUMUOBIAKANI', 'PHC', 'S1', 'CODO', 'NG', 1, datetime.datetime(2025, 10, 4, 14, 55, 42, 188546, tzinfo=datetime.timezone.utc)), ('NG111S0263', 'JS TARKA', 'ABUJA 1', 'S1', 'CODO', 'NG', 1, datetime.datetime(2025, 10, 4, 14, 55, 42, 188546, tzinfo=datetime.timezone.utc)), ('NG111S0268', 'SULTAN ABUBAKAR', 'ABUJA 2', 'S1', 'CODO', 'NG', 1, datetime.datetime(2025, 10, 4, 14, 55, 42, 188546, tzinfo=datetime.timezone.utc)), ('NG111S0271', 'WUSE 1', 'ABUJA 2', 'S1', 'CODO', 'NG', 1, datetime.datetime(2025, 10, 4, 14, 55, 42, 188546, tzinfo=datetime.timezone.utc)), ('NG111S0571', 'TIPPER GARAGE S/S', 'ABUJA 3', 'S2', 'CODO', 'NG', 1, datetime.datetime(2025, 10, 4, 14, 55, 42, 188546, tzinfo=datetime.timezone.utc)), ('NG111S0159', 'CALABAR RD SS', 'CALABAR', 'S1', 'CODO', 'NG', 1, datetime.datetime(2025, 10, 4, 14, 55, 42, 188546, tzinfo=datetime.timezone.utc))  ... displaying 10 of 500 total bound parameter sets ...  ('YT245', 'Station de Kaweni', 'Mamoudzou', 'S1', 'COCO', 'YT', 1, datetime.datetime(2025, 10, 4, 14, 55, 42, 188546, tzinfo=datetime.timezone.utc)), ('YT246', 'Station de Longoni', 'Koungou', 'S3', 'COCO', 'YT', 1, datetime.datetime(2025, 10, 4, 14, 55, 42, 188546, tzinfo=datetime.timezone.utc)))]
(Background on this error at: https://sqlalche.me/e/14/e3q8)
[2025-10-04T14:55:46.698+0000] {taskinstance.py:1138} INFO - Marking task as FAILED. dag_id=etl_pipeline_scd2, task_id=load_to_dw_scd2, execution_date=20251004T145338, start_date=20251004T145539, end_date=20251004T145546
[2025-10-04T14:55:46.732+0000] {standard_task_runner.py:107} ERROR - Failed to execute job 103 for task load_to_dw_scd2 ((MySQLdb.OperationalError) (1054, "Unknown column 'station_name' in 'field list'")
[SQL: INSERT INTO `dim_stations` (`cost_center`, `station_name`, `city`, `segmentation`, `management_method`, `code_du_pays`, `is_current`, `start_date`) VALUES (%s, %s, %s, %s, %s, %s, %s, %s)]
[parameters: (('NG111S0307', 'DOKA CRS SS', 'KADUNA', 'S1', 'CODO', 'NG', 1, datetime.datetime(2025, 10, 4, 14, 55, 42, 188546, tzinfo=datetime.timezone.utc)), ('NG111S0313', 'SOUTH BRIDGE', 'KADUNA', 'S1', 'CODO', 'NG', 1, datetime.datetime(2025, 10, 4, 14, 55, 42, 188546, tzinfo=datetime.timezone.utc)), ('NG111S0206', 'RUMUOBIAKANI', 'PHC', 'S1', 'CODO', 'NG', 1, datetime.datetime(2025, 10, 4, 14, 55, 42, 188546, tzinfo=datetime.timezone.utc)), ('NG111S0263', 'JS TARKA', 'ABUJA 1', 'S1', 'CODO', 'NG', 1, datetime.datetime(2025, 10, 4, 14, 55, 42, 188546, tzinfo=datetime.timezone.utc)), ('NG111S0268', 'SULTAN ABUBAKAR', 'ABUJA 2', 'S1', 'CODO', 'NG', 1, datetime.datetime(2025, 10, 4, 14, 55, 42, 188546, tzinfo=datetime.timezone.utc)), ('NG111S0271', 'WUSE 1', 'ABUJA 2', 'S1', 'CODO', 'NG', 1, datetime.datetime(2025, 10, 4, 14, 55, 42, 188546, tzinfo=datetime.timezone.utc)), ('NG111S0571', 'TIPPER GARAGE S/S', 'ABUJA 3', 'S2', 'CODO', 'NG', 1, datetime.datetime(2025, 10, 4, 14, 55, 42, 188546, tzinfo=datetime.timezone.utc)), ('NG111S0159', 'CALABAR RD SS', 'CALABAR', 'S1', 'CODO', 'NG', 1, datetime.datetime(2025, 10, 4, 14, 55, 42, 188546, tzinfo=datetime.timezone.utc))  ... displaying 10 of 500 total bound parameter sets ...  ('YT245', 'Station de Kaweni', 'Mamoudzou', 'S1', 'COCO', 'YT', 1, datetime.datetime(2025, 10, 4, 14, 55, 42, 188546, tzinfo=datetime.timezone.utc)), ('YT246', 'Station de Longoni', 'Koungou', 'S3', 'COCO', 'YT', 1, datetime.datetime(2025, 10, 4, 14, 55, 42, 188546, tzinfo=datetime.timezone.utc)))]
(Background on this error at: https://sqlalche.me/e/14/e3q8); 652)
[2025-10-04T14:55:46.797+0000] {local_task_job_runner.py:234} INFO - Task exited with return code 1
[2025-10-04T14:55:46.817+0000] {taskinstance.py:3280} INFO - 0 downstream tasks scheduled from follow-on schedule check
