[2025-10-04T14:22:44.074+0000] {taskinstance.py:1956} INFO - Dependencies all met for dep_context=non-requeueable deps ti=<TaskInstance: etl_pipeline_scd2.load_to_dw_scd2 manual__2025-10-04T14:21:10.270411+00:00 [queued]>
[2025-10-04T14:22:44.120+0000] {taskinstance.py:1956} INFO - Dependencies all met for dep_context=requeueable deps ti=<TaskInstance: etl_pipeline_scd2.load_to_dw_scd2 manual__2025-10-04T14:21:10.270411+00:00 [queued]>
[2025-10-04T14:22:44.122+0000] {taskinstance.py:2170} INFO - Starting attempt 1 of 1
[2025-10-04T14:22:44.203+0000] {taskinstance.py:2191} INFO - Executing <Task(PythonOperator): load_to_dw_scd2> on 2025-10-04 14:21:10.270411+00:00
[2025-10-04T14:22:44.230+0000] {standard_task_runner.py:60} INFO - Started process 274 to run task
[2025-10-04T14:22:44.258+0000] {standard_task_runner.py:87} INFO - Running: ['***', 'tasks', 'run', 'etl_pipeline_scd2', 'load_to_dw_scd2', 'manual__2025-10-04T14:21:10.270411+00:00', '--job-id', '98', '--raw', '--subdir', 'DAGS_FOLDER/process_scripts.py', '--cfg-path', '/tmp/tmpy4vpixrp']
[2025-10-04T14:22:44.268+0000] {standard_task_runner.py:88} INFO - Job 98: Subtask load_to_dw_scd2
[2025-10-04T14:22:44.406+0000] {logging_mixin.py:188} WARNING - /home/***/.local/lib/python3.11/site-packages/***/settings.py:194 DeprecationWarning: The sql_alchemy_conn option in [core] has been moved to the sql_alchemy_conn option in [database] - the old setting has been used, but please update your config.
[2025-10-04T14:22:44.577+0000] {task_command.py:423} INFO - Running <TaskInstance: etl_pipeline_scd2.load_to_dw_scd2 manual__2025-10-04T14:21:10.270411+00:00 [running]> on host 28712a281084
[2025-10-04T14:22:44.866+0000] {taskinstance.py:2480} INFO - Exporting env vars: AIRFLOW_CTX_DAG_OWNER='***' AIRFLOW_CTX_DAG_ID='etl_pipeline_scd2' AIRFLOW_CTX_TASK_ID='load_to_dw_scd2' AIRFLOW_CTX_EXECUTION_DATE='2025-10-04T14:21:10.270411+00:00' AIRFLOW_CTX_TRY_NUMBER='1' AIRFLOW_CTX_DAG_RUN_ID='manual__2025-10-04T14:21:10.270411+00:00'
[2025-10-04T14:22:48.485+0000] {scd2_loader.py:213} INFO - üìÇ Traitement du fichier: Country_code.xlsx
[2025-10-04T14:22:53.501+0000] {scd2_loader.py:255} WARNING - 1 lignes ignor√©es (cl√©s manquantes) dans Country_code.xlsx::0
[2025-10-04T14:22:53.994+0000] {scd2_loader.py:168} INFO - ‚ö†Ô∏è Doublon ignor√© pour dim_pays cl√©=('NG',)
[2025-10-04T14:22:53.996+0000] {scd2_loader.py:168} INFO - ‚ö†Ô∏è Doublon ignor√© pour dim_pays cl√©=('YT',)
[2025-10-04T14:22:53.997+0000] {scd2_loader.py:168} INFO - ‚ö†Ô∏è Doublon ignor√© pour dim_pays cl√©=('ER',)
[2025-10-04T14:22:53.998+0000] {scd2_loader.py:168} INFO - ‚ö†Ô∏è Doublon ignor√© pour dim_pays cl√©=('ET',)
[2025-10-04T14:22:53.999+0000] {scd2_loader.py:168} INFO - ‚ö†Ô∏è Doublon ignor√© pour dim_pays cl√©=('MG',)
[2025-10-04T14:22:54.000+0000] {scd2_loader.py:168} INFO - ‚ö†Ô∏è Doublon ignor√© pour dim_pays cl√©=('MA',)
[2025-10-04T14:22:54.002+0000] {scd2_loader.py:168} INFO - ‚ö†Ô∏è Doublon ignor√© pour dim_pays cl√©=('MU',)
[2025-10-04T14:22:54.003+0000] {scd2_loader.py:168} INFO - ‚ö†Ô∏è Doublon ignor√© pour dim_pays cl√©=('RE',)
[2025-10-04T14:22:54.004+0000] {scd2_loader.py:168} INFO - ‚ö†Ô∏è Doublon ignor√© pour dim_pays cl√©=('TN',)
[2025-10-04T14:22:54.006+0000] {scd2_loader.py:168} INFO - ‚ö†Ô∏è Doublon ignor√© pour dim_pays cl√©=('TG',)
[2025-10-04T14:22:54.006+0000] {scd2_loader.py:168} INFO - ‚ö†Ô∏è Doublon ignor√© pour dim_pays cl√©=('TD',)
[2025-10-04T14:22:54.007+0000] {scd2_loader.py:168} INFO - ‚ö†Ô∏è Doublon ignor√© pour dim_pays cl√©=('SN',)
[2025-10-04T14:22:54.008+0000] {scd2_loader.py:168} INFO - ‚ö†Ô∏è Doublon ignor√© pour dim_pays cl√©=('ML',)
[2025-10-04T14:22:54.010+0000] {scd2_loader.py:168} INFO - ‚ö†Ô∏è Doublon ignor√© pour dim_pays cl√©=('GH',)
[2025-10-04T14:22:54.011+0000] {scd2_loader.py:168} INFO - ‚ö†Ô∏è Doublon ignor√© pour dim_pays cl√©=('GN',)
[2025-10-04T14:22:54.012+0000] {scd2_loader.py:168} INFO - ‚ö†Ô∏è Doublon ignor√© pour dim_pays cl√©=('BW',)
[2025-10-04T14:22:54.013+0000] {scd2_loader.py:168} INFO - ‚ö†Ô∏è Doublon ignor√© pour dim_pays cl√©=('ZA',)
[2025-10-04T14:22:54.014+0000] {scd2_loader.py:168} INFO - ‚ö†Ô∏è Doublon ignor√© pour dim_pays cl√©=('SZ',)
[2025-10-04T14:22:54.016+0000] {scd2_loader.py:168} INFO - ‚ö†Ô∏è Doublon ignor√© pour dim_pays cl√©=('MW',)
[2025-10-04T14:22:54.017+0000] {scd2_loader.py:168} INFO - ‚ö†Ô∏è Doublon ignor√© pour dim_pays cl√©=('AO',)
[2025-10-04T14:22:54.019+0000] {scd2_loader.py:168} INFO - ‚ö†Ô∏è Doublon ignor√© pour dim_pays cl√©=('MZ',)
[2025-10-04T14:22:54.020+0000] {scd2_loader.py:168} INFO - ‚ö†Ô∏è Doublon ignor√© pour dim_pays cl√©=('ZW',)
[2025-10-04T14:22:54.021+0000] {scd2_loader.py:168} INFO - ‚ö†Ô∏è Doublon ignor√© pour dim_pays cl√©=('ZM',)
[2025-10-04T14:22:54.023+0000] {scd2_loader.py:168} INFO - ‚ö†Ô∏è Doublon ignor√© pour dim_pays cl√©=('CM',)
[2025-10-04T14:22:54.024+0000] {scd2_loader.py:168} INFO - ‚ö†Ô∏è Doublon ignor√© pour dim_pays cl√©=('CD',)
[2025-10-04T14:22:54.025+0000] {scd2_loader.py:168} INFO - ‚ö†Ô∏è Doublon ignor√© pour dim_pays cl√©=('GA',)
[2025-10-04T14:22:54.027+0000] {scd2_loader.py:168} INFO - ‚ö†Ô∏è Doublon ignor√© pour dim_pays cl√©=('KE',)
[2025-10-04T14:22:54.028+0000] {scd2_loader.py:168} INFO - ‚ö†Ô∏è Doublon ignor√© pour dim_pays cl√©=('UG',)
[2025-10-04T14:22:54.029+0000] {scd2_loader.py:168} INFO - ‚ö†Ô∏è Doublon ignor√© pour dim_pays cl√©=('TZ',)
[2025-10-04T14:22:54.030+0000] {scd2_loader.py:194} INFO - [SCD2] dim_pays ‚Üí inserts=0, updates_closed=0
[2025-10-04T14:22:54.030+0000] {scd2_loader.py:213} INFO - üìÇ Traitement du fichier: Extract_Station.xlsx
[2025-10-04T14:22:54.972+0000] {scd2_loader.py:255} WARNING - 3277 lignes ignor√©es (cl√©s manquantes) dans Extract_Station.xlsx::0
[2025-10-04T14:22:55.568+0000] {taskinstance.py:2698} ERROR - Task failed with exception
Traceback (most recent call last):
  File "/home/airflow/.local/lib/python3.11/site-packages/sqlalchemy/engine/base.py", line 1810, in _execute_context
    context = constructor(
              ^^^^^^^^^^^^
  File "/home/airflow/.local/lib/python3.11/site-packages/sqlalchemy/engine/default.py", line 1001, in _init_compiled
    self.compiled_parameters = [
                               ^
  File "/home/airflow/.local/lib/python3.11/site-packages/sqlalchemy/engine/default.py", line 1002, in <listcomp>
    compiled.construct_params(
  File "/home/airflow/.local/lib/python3.11/site-packages/sqlalchemy/sql/compiler.py", line 1026, in construct_params
    raise exc.InvalidRequestError(
sqlalchemy.exc.InvalidRequestError: A value is required for bind parameter 'dodo_cash_' (Background on this error at: https://sqlalche.me/e/14/cd3x)

The above exception was the direct cause of the following exception:

Traceback (most recent call last):
  File "/home/airflow/.local/lib/python3.11/site-packages/airflow/models/taskinstance.py", line 433, in _execute_task
    result = execute_callable(context=context, **execute_callable_kwargs)
             ^^^^^^^^^^^^^^^^^^^^^^^^^^^^^^^^^^^^^^^^^^^^^^^^^^^^^^^^^^^^
  File "/home/airflow/.local/lib/python3.11/site-packages/airflow/operators/python.py", line 199, in execute
    return_value = self.execute_callable()
                   ^^^^^^^^^^^^^^^^^^^^^^^
  File "/home/airflow/.local/lib/python3.11/site-packages/airflow/operators/python.py", line 216, in execute_callable
    return self.python_callable(*self.op_args, **self.op_kwargs)
           ^^^^^^^^^^^^^^^^^^^^^^^^^^^^^^^^^^^^^^^^^^^^^^^^^^^^^
  File "/opt/airflow/dags/process_scripts.py", line 28, in run_scd2_loader
    load_all_out_files_to_dw()
  File "/opt/airflow/dags/scd2_loader.py", line 257, in load_all_out_files_to_dw
    ins, upd = _process_table_batch(engine, table_name, df, business_keys, now)
               ^^^^^^^^^^^^^^^^^^^^^^^^^^^^^^^^^^^^^^^^^^^^^^^^^^^^^^^^^^^^^^^^
  File "/opt/airflow/dags/scd2_loader.py", line 190, in _process_table_batch
    conn.execute(insert_sql, chunk)
  File "/home/airflow/.local/lib/python3.11/site-packages/sqlalchemy/engine/base.py", line 1385, in execute
    return meth(self, multiparams, params, _EMPTY_EXECUTION_OPTS)
           ^^^^^^^^^^^^^^^^^^^^^^^^^^^^^^^^^^^^^^^^^^^^^^^^^^^^^^
  File "/home/airflow/.local/lib/python3.11/site-packages/sqlalchemy/sql/elements.py", line 334, in _execute_on_connection
    return connection._execute_clauseelement(
           ^^^^^^^^^^^^^^^^^^^^^^^^^^^^^^^^^^
  File "/home/airflow/.local/lib/python3.11/site-packages/sqlalchemy/engine/base.py", line 1577, in _execute_clauseelement
    ret = self._execute_context(
          ^^^^^^^^^^^^^^^^^^^^^^
  File "/home/airflow/.local/lib/python3.11/site-packages/sqlalchemy/engine/base.py", line 1816, in _execute_context
    self._handle_dbapi_exception(
  File "/home/airflow/.local/lib/python3.11/site-packages/sqlalchemy/engine/base.py", line 2134, in _handle_dbapi_exception
    util.raise_(
  File "/home/airflow/.local/lib/python3.11/site-packages/sqlalchemy/util/compat.py", line 211, in raise_
    raise exception
  File "/home/airflow/.local/lib/python3.11/site-packages/sqlalchemy/engine/base.py", line 1810, in _execute_context
    context = constructor(
              ^^^^^^^^^^^^
  File "/home/airflow/.local/lib/python3.11/site-packages/sqlalchemy/engine/default.py", line 1001, in _init_compiled
    self.compiled_parameters = [
                               ^
  File "/home/airflow/.local/lib/python3.11/site-packages/sqlalchemy/engine/default.py", line 1002, in <listcomp>
    compiled.construct_params(
  File "/home/airflow/.local/lib/python3.11/site-packages/sqlalchemy/sql/compiler.py", line 1026, in construct_params
    raise exc.InvalidRequestError(
sqlalchemy.exc.StatementError: (sqlalchemy.exc.InvalidRequestError) A value is required for bind parameter 'dodo_cash_'
[SQL: INSERT INTO `dim_stations` (`cost_center`, `dodo_cash_|_name`, `city`, `dodo_vl_|_segmentation_(s1,_s2,_s3,_s4)`, `management_method`, `code_pays`, `centre_de_co√ªt`, `nom_de_la_station`, `ville`, `segmentation_(s1,_s2,_s3,_s4)`, `mode_de_gestion`, `name`, `date_of_update_|_cost_center`, `2024-07-29_00:00:00_|_name`, `segmentation_(s1,_s2,_s3,_s4)`, `2024-06-25_00:00:00_|_name`, `update_date_|_cost_center`, `2024-09-20_00:00:00_|_name`, `cost_centre`, `management_method`, `14/15/2025_|_name`, `is_current`, `start_date`) VALUES (%s, %s|_name, %s, %s|_segmentation_(s1,_s2,_s3,_s4), %s, %s, %s, %s, %s, %s(s1,_s2,_s3,_s4), %s, %s, %s|_cost_center, %s-07-29_00:00:00_|_name, %s(s1,_s2,_s3,_s4), %s-06-25_00:00:00_|_name, %s|_cost_center, %s-09-20_00:00:00_|_name, %s, %s, %s/15/2025_|_name, %s, %s)]
[parameters: [{'cost_center': 'NG111S0307', 'dodo_cash_|_name': 'DOKA CRS SS', 'city': 'KADUNA', 'dodo_vl_|_segmentation_(s1,_s2,_s3,_s4)': 'S1', 'management_metho ... (415918 characters truncated) ... e': None, '14/15/2025_|_name': None, 'is_current': 1, 'start_date': datetime.datetime(2025, 10, 4, 14, 22, 48, 471439, tzinfo=datetime.timezone.utc)}]]
(Background on this error at: https://sqlalche.me/e/14/cd3x)
[2025-10-04T14:22:55.805+0000] {taskinstance.py:1138} INFO - Marking task as FAILED. dag_id=etl_pipeline_scd2, task_id=load_to_dw_scd2, execution_date=20251004T142110, start_date=20251004T142244, end_date=20251004T142255
[2025-10-04T14:22:55.862+0000] {standard_task_runner.py:107} ERROR - Failed to execute job 98 for task load_to_dw_scd2 ((sqlalchemy.exc.InvalidRequestError) A value is required for bind parameter 'dodo_cash_'
[SQL: INSERT INTO `dim_stations` (`cost_center`, `dodo_cash_|_name`, `city`, `dodo_vl_|_segmentation_(s1,_s2,_s3,_s4)`, `management_method`, `code_pays`, `centre_de_co√ªt`, `nom_de_la_station`, `ville`, `segmentation_(s1,_s2,_s3,_s4)`, `mode_de_gestion`, `name`, `date_of_update_|_cost_center`, `2024-07-29_00:00:00_|_name`, `segmentation_(s1,_s2,_s3,_s4)`, `2024-06-25_00:00:00_|_name`, `update_date_|_cost_center`, `2024-09-20_00:00:00_|_name`, `cost_centre`, `management_method`, `14/15/2025_|_name`, `is_current`, `start_date`) VALUES (%s, %s|_name, %s, %s|_segmentation_(s1,_s2,_s3,_s4), %s, %s, %s, %s, %s, %s(s1,_s2,_s3,_s4), %s, %s, %s|_cost_center, %s-07-29_00:00:00_|_name, %s(s1,_s2,_s3,_s4), %s-06-25_00:00:00_|_name, %s|_cost_center, %s-09-20_00:00:00_|_name, %s, %s, %s/15/2025_|_name, %s, %s)]
[parameters: [{'cost_center': 'NG111S0307', 'dodo_cash_|_name': 'DOKA CRS SS', 'city': 'KADUNA', 'dodo_vl_|_segmentation_(s1,_s2,_s3,_s4)': 'S1', 'management_metho ... (415918 characters truncated) ... e': None, '14/15/2025_|_name': None, 'is_current': 1, 'start_date': datetime.datetime(2025, 10, 4, 14, 22, 48, 471439, tzinfo=datetime.timezone.utc)}]]
(Background on this error at: https://sqlalche.me/e/14/cd3x); 274)
[2025-10-04T14:22:56.030+0000] {local_task_job_runner.py:234} INFO - Task exited with return code 1
[2025-10-04T14:22:56.082+0000] {taskinstance.py:3280} INFO - 0 downstream tasks scheduled from follow-on schedule check
