[2025-10-07T17:19:42.393+0000] {taskinstance.py:1956} INFO - Dependencies all met for dep_context=non-requeueable deps ti=<TaskInstance: etl_pipeline_scd2.load_to_dw_scd2 manual__2025-10-07T17:17:02.629224+00:00 [queued]>
[2025-10-07T17:19:42.507+0000] {taskinstance.py:1956} INFO - Dependencies all met for dep_context=requeueable deps ti=<TaskInstance: etl_pipeline_scd2.load_to_dw_scd2 manual__2025-10-07T17:17:02.629224+00:00 [queued]>
[2025-10-07T17:19:42.511+0000] {taskinstance.py:2170} INFO - Starting attempt 1 of 1
[2025-10-07T17:19:42.663+0000] {taskinstance.py:2191} INFO - Executing <Task(PythonOperator): load_to_dw_scd2> on 2025-10-07 17:17:02.629224+00:00
[2025-10-07T17:19:42.709+0000] {standard_task_runner.py:60} INFO - Started process 1469 to run task
[2025-10-07T17:19:42.750+0000] {standard_task_runner.py:87} INFO - Running: ['***', 'tasks', 'run', 'etl_pipeline_scd2', 'load_to_dw_scd2', 'manual__2025-10-07T17:17:02.629224+00:00', '--job-id', '293', '--raw', '--subdir', 'DAGS_FOLDER/process_scripts.py', '--cfg-path', '/tmp/tmpl039yl6b']
[2025-10-07T17:19:42.765+0000] {standard_task_runner.py:88} INFO - Job 293: Subtask load_to_dw_scd2
[2025-10-07T17:19:42.843+0000] {logging_mixin.py:188} WARNING - /home/***/.local/lib/python3.11/site-packages/***/settings.py:194 DeprecationWarning: The sql_alchemy_conn option in [core] has been moved to the sql_alchemy_conn option in [database] - the old setting has been used, but please update your config.
[2025-10-07T17:19:43.025+0000] {task_command.py:423} INFO - Running <TaskInstance: etl_pipeline_scd2.load_to_dw_scd2 manual__2025-10-07T17:17:02.629224+00:00 [running]> on host b96e3b23df3a
[2025-10-07T17:19:43.252+0000] {taskinstance.py:2480} INFO - Exporting env vars: AIRFLOW_CTX_DAG_OWNER='***' AIRFLOW_CTX_DAG_ID='etl_pipeline_scd2' AIRFLOW_CTX_TASK_ID='load_to_dw_scd2' AIRFLOW_CTX_EXECUTION_DATE='2025-10-07T17:17:02.629224+00:00' AIRFLOW_CTX_TRY_NUMBER='1' AIRFLOW_CTX_DAG_RUN_ID='manual__2025-10-07T17:17:02.629224+00:00'
[2025-10-07T17:19:45.972+0000] {taskinstance.py:2698} ERROR - Task failed with exception
Traceback (most recent call last):
  File "/home/airflow/.local/lib/python3.11/site-packages/airflow/models/taskinstance.py", line 433, in _execute_task
    result = execute_callable(context=context, **execute_callable_kwargs)
             ^^^^^^^^^^^^^^^^^^^^^^^^^^^^^^^^^^^^^^^^^^^^^^^^^^^^^^^^^^^^
  File "/home/airflow/.local/lib/python3.11/site-packages/airflow/operators/python.py", line 199, in execute
    return_value = self.execute_callable()
                   ^^^^^^^^^^^^^^^^^^^^^^^
  File "/home/airflow/.local/lib/python3.11/site-packages/airflow/operators/python.py", line 216, in execute_callable
    return self.python_callable(*self.op_args, **self.op_kwargs)
           ^^^^^^^^^^^^^^^^^^^^^^^^^^^^^^^^^^^^^^^^^^^^^^^^^^^^^
  File "/opt/airflow/dags/process_scripts.py", line 28, in run_scd2_loader
    load_all_out_files_to_dw()
  File "/opt/airflow/dags/scd2_loader.py", line 99, in load_all_out_files_to_dw
    conn = get_connection()
           ^^^^^^^^^^^^^^^^
  File "/opt/airflow/dags/scd2_loader.py", line 31, in get_connection
    return mysql.connector.connect(**DB_CONFIG)
                                     ^^^^^^^^^
NameError: name 'DB_CONFIG' is not defined
[2025-10-07T17:19:46.001+0000] {taskinstance.py:1138} INFO - Marking task as FAILED. dag_id=etl_pipeline_scd2, task_id=load_to_dw_scd2, execution_date=20251007T171702, start_date=20251007T171942, end_date=20251007T171945
[2025-10-07T17:19:46.045+0000] {standard_task_runner.py:107} ERROR - Failed to execute job 293 for task load_to_dw_scd2 (name 'DB_CONFIG' is not defined; 1469)
[2025-10-07T17:19:46.109+0000] {local_task_job_runner.py:234} INFO - Task exited with return code 1
[2025-10-07T17:19:46.139+0000] {taskinstance.py:3280} INFO - 0 downstream tasks scheduled from follow-on schedule check
