[2025-10-07T16:48:24.624+0000] {taskinstance.py:1956} INFO - Dependencies all met for dep_context=non-requeueable deps ti=<TaskInstance: etl_pipeline_scd2.load_to_dw_scd2 manual__2025-10-07T16:45:32.839687+00:00 [queued]>
[2025-10-07T16:48:24.669+0000] {taskinstance.py:1956} INFO - Dependencies all met for dep_context=requeueable deps ti=<TaskInstance: etl_pipeline_scd2.load_to_dw_scd2 manual__2025-10-07T16:45:32.839687+00:00 [queued]>
[2025-10-07T16:48:24.670+0000] {taskinstance.py:2170} INFO - Starting attempt 1 of 1
[2025-10-07T16:48:24.731+0000] {taskinstance.py:2191} INFO - Executing <Task(PythonOperator): load_to_dw_scd2> on 2025-10-07 16:45:32.839687+00:00
[2025-10-07T16:48:24.755+0000] {standard_task_runner.py:60} INFO - Started process 920 to run task
[2025-10-07T16:48:24.797+0000] {standard_task_runner.py:87} INFO - Running: ['***', 'tasks', 'run', 'etl_pipeline_scd2', 'load_to_dw_scd2', 'manual__2025-10-07T16:45:32.839687+00:00', '--job-id', '275', '--raw', '--subdir', 'DAGS_FOLDER/process_scripts.py', '--cfg-path', '/tmp/tmp95vofbyk']
[2025-10-07T16:48:24.829+0000] {standard_task_runner.py:88} INFO - Job 275: Subtask load_to_dw_scd2
[2025-10-07T16:48:24.922+0000] {logging_mixin.py:188} WARNING - /home/***/.local/lib/python3.11/site-packages/***/settings.py:194 DeprecationWarning: The sql_alchemy_conn option in [core] has been moved to the sql_alchemy_conn option in [database] - the old setting has been used, but please update your config.
[2025-10-07T16:48:25.127+0000] {task_command.py:423} INFO - Running <TaskInstance: etl_pipeline_scd2.load_to_dw_scd2 manual__2025-10-07T16:45:32.839687+00:00 [running]> on host b96e3b23df3a
[2025-10-07T16:48:25.433+0000] {taskinstance.py:2480} INFO - Exporting env vars: AIRFLOW_CTX_DAG_OWNER='***' AIRFLOW_CTX_DAG_ID='etl_pipeline_scd2' AIRFLOW_CTX_TASK_ID='load_to_dw_scd2' AIRFLOW_CTX_EXECUTION_DATE='2025-10-07T16:45:32.839687+00:00' AIRFLOW_CTX_TRY_NUMBER='1' AIRFLOW_CTX_DAG_RUN_ID='manual__2025-10-07T16:45:32.839687+00:00'
[2025-10-07T16:48:28.342+0000] {taskinstance.py:2698} ERROR - Task failed with exception
Traceback (most recent call last):
  File "/home/airflow/.local/lib/python3.11/site-packages/mysql/connector/network.py", line 574, in open_connection
    self.sock.connect(sockaddr)
ConnectionRefusedError: [Errno 111] Connection refused

During handling of the above exception, another exception occurred:

Traceback (most recent call last):
  File "/home/airflow/.local/lib/python3.11/site-packages/airflow/models/taskinstance.py", line 433, in _execute_task
    result = execute_callable(context=context, **execute_callable_kwargs)
             ^^^^^^^^^^^^^^^^^^^^^^^^^^^^^^^^^^^^^^^^^^^^^^^^^^^^^^^^^^^^
  File "/home/airflow/.local/lib/python3.11/site-packages/airflow/operators/python.py", line 199, in execute
    return_value = self.execute_callable()
                   ^^^^^^^^^^^^^^^^^^^^^^^
  File "/home/airflow/.local/lib/python3.11/site-packages/airflow/operators/python.py", line 216, in execute_callable
    return self.python_callable(*self.op_args, **self.op_kwargs)
           ^^^^^^^^^^^^^^^^^^^^^^^^^^^^^^^^^^^^^^^^^^^^^^^^^^^^^
  File "/opt/airflow/dags/process_scripts.py", line 28, in run_scd2_loader
    load_scd2_data()
  File "/opt/airflow/dags/scd2_loader.py", line 139, in load_scd2_data
    conn = get_connection()
           ^^^^^^^^^^^^^^^^
  File "/opt/airflow/dags/scd2_loader.py", line 46, in get_connection
    return mysql.connector.connect(**DB_CONFIG)
           ^^^^^^^^^^^^^^^^^^^^^^^^^^^^^^^^^^^^
  File "/home/airflow/.local/lib/python3.11/site-packages/mysql/connector/__init__.py", line 273, in connect
    return MySQLConnection(*args, **kwargs)
           ^^^^^^^^^^^^^^^^^^^^^^^^^^^^^^^^
  File "/home/airflow/.local/lib/python3.11/site-packages/mysql/connector/connection.py", line 116, in __init__
    self.connect(**kwargs)
  File "/home/airflow/.local/lib/python3.11/site-packages/mysql/connector/abstracts.py", line 1052, in connect
    self._open_connection()
  File "/home/airflow/.local/lib/python3.11/site-packages/mysql/connector/connection.py", line 494, in _open_connection
    self._socket.open_connection()
  File "/home/airflow/.local/lib/python3.11/site-packages/mysql/connector/network.py", line 576, in open_connection
    raise errors.InterfaceError(
mysql.connector.errors.InterfaceError: 2003: Can't connect to MySQL server on 'localhost:3306' (111 Connection refused)
[2025-10-07T16:48:28.424+0000] {taskinstance.py:1138} INFO - Marking task as FAILED. dag_id=etl_pipeline_scd2, task_id=load_to_dw_scd2, execution_date=20251007T164532, start_date=20251007T164824, end_date=20251007T164828
[2025-10-07T16:48:28.476+0000] {standard_task_runner.py:107} ERROR - Failed to execute job 275 for task load_to_dw_scd2 (2003: Can't connect to MySQL server on 'localhost:3306' (111 Connection refused); 920)
[2025-10-07T16:48:28.523+0000] {local_task_job_runner.py:234} INFO - Task exited with return code 1
[2025-10-07T16:48:28.557+0000] {taskinstance.py:3280} INFO - 0 downstream tasks scheduled from follow-on schedule check
