[2025-10-05T20:27:14.483+0000] {taskinstance.py:1956} INFO - Dependencies all met for dep_context=non-requeueable deps ti=<TaskInstance: etl_pipeline_scd2.run_processor_harmonizer manual__2025-10-05T20:25:57.046587+00:00 [queued]>
[2025-10-05T20:27:14.498+0000] {taskinstance.py:1956} INFO - Dependencies all met for dep_context=requeueable deps ti=<TaskInstance: etl_pipeline_scd2.run_processor_harmonizer manual__2025-10-05T20:25:57.046587+00:00 [queued]>
[2025-10-05T20:27:14.499+0000] {taskinstance.py:2170} INFO - Starting attempt 1 of 1
[2025-10-05T20:27:14.527+0000] {taskinstance.py:2191} INFO - Executing <Task(PythonOperator): run_processor_harmonizer> on 2025-10-05 20:25:57.046587+00:00
[2025-10-05T20:27:14.544+0000] {standard_task_runner.py:60} INFO - Started process 306 to run task
[2025-10-05T20:27:14.550+0000] {standard_task_runner.py:87} INFO - Running: ['***', 'tasks', 'run', 'etl_pipeline_scd2', 'run_processor_harmonizer', 'manual__2025-10-05T20:25:57.046587+00:00', '--job-id', '129', '--raw', '--subdir', 'DAGS_FOLDER/process_scripts.py', '--cfg-path', '/tmp/tmp4br4vw3p']
[2025-10-05T20:27:14.553+0000] {standard_task_runner.py:88} INFO - Job 129: Subtask run_processor_harmonizer
[2025-10-05T20:27:14.582+0000] {logging_mixin.py:188} WARNING - /home/***/.local/lib/python3.11/site-packages/***/settings.py:194 DeprecationWarning: The sql_alchemy_conn option in [core] has been moved to the sql_alchemy_conn option in [database] - the old setting has been used, but please update your config.
[2025-10-05T20:27:14.690+0000] {task_command.py:423} INFO - Running <TaskInstance: etl_pipeline_scd2.run_processor_harmonizer manual__2025-10-05T20:25:57.046587+00:00 [running]> on host 61b2e37950d0
[2025-10-05T20:27:14.799+0000] {taskinstance.py:2480} INFO - Exporting env vars: AIRFLOW_CTX_DAG_OWNER='***' AIRFLOW_CTX_DAG_ID='etl_pipeline_scd2' AIRFLOW_CTX_TASK_ID='run_processor_harmonizer' AIRFLOW_CTX_EXECUTION_DATE='2025-10-05T20:25:57.046587+00:00' AIRFLOW_CTX_TRY_NUMBER='1' AIRFLOW_CTX_DAG_RUN_ID='manual__2025-10-05T20:25:57.046587+00:00'
[2025-10-05T20:27:16.263+0000] {taskinstance.py:2698} ERROR - Task failed with exception
Traceback (most recent call last):
  File "/home/airflow/.local/lib/python3.11/site-packages/airflow/models/taskinstance.py", line 433, in _execute_task
    result = execute_callable(context=context, **execute_callable_kwargs)
             ^^^^^^^^^^^^^^^^^^^^^^^^^^^^^^^^^^^^^^^^^^^^^^^^^^^^^^^^^^^^
  File "/home/airflow/.local/lib/python3.11/site-packages/airflow/operators/python.py", line 199, in execute
    return_value = self.execute_callable()
                   ^^^^^^^^^^^^^^^^^^^^^^^
  File "/home/airflow/.local/lib/python3.11/site-packages/airflow/operators/python.py", line 216, in execute_callable
    return self.python_callable(*self.op_args, **self.op_kwargs)
           ^^^^^^^^^^^^^^^^^^^^^^^^^^^^^^^^^^^^^^^^^^^^^^^^^^^^^
  File "/opt/airflow/dags/process_scripts.py", line 20, in run_script
    raise Exception(f"Script {script_path} failed\nSTDOUT:{result.stdout}\nSTDERR:{result.stderr}")
Exception: Script /opt/***/scripts/processor_harmonizer.py failed
STDOUT:
STDERR:Traceback (most recent call last):
  File "/opt/***/scripts/processor_harmonizer.py", line 103, in <module>
    update_files_from_hse_similarity()
  File "/opt/***/scripts/processor_harmonizer.py", line 39, in update_files_from_hse_similarity
    ref_by_country = {k: v.copy() for k, v in ref.groupby(country_col)}
                                              ^^^^^^^^^^^^^^^^^^^^^^^^
  File "/home/***/.local/lib/python3.11/site-packages/pandas/core/frame.py", line 8869, in groupby
    return DataFrameGroupBy(
           ^^^^^^^^^^^^^^^^^
  File "/home/***/.local/lib/python3.11/site-packages/pandas/core/groupby/groupby.py", line 1278, in __init__
    grouper, exclusions, obj = get_grouper(
                               ^^^^^^^^^^^^
  File "/home/***/.local/lib/python3.11/site-packages/pandas/core/groupby/grouper.py", line 1009, in get_grouper
    raise KeyError(gpr)
KeyError: 'Code du pays'

[2025-10-05T20:27:16.292+0000] {taskinstance.py:1138} INFO - Marking task as FAILED. dag_id=etl_pipeline_scd2, task_id=run_processor_harmonizer, execution_date=20251005T202557, start_date=20251005T202714, end_date=20251005T202716
[2025-10-05T20:27:16.339+0000] {standard_task_runner.py:107} ERROR - Failed to execute job 129 for task run_processor_harmonizer (Script /opt/***/scripts/processor_harmonizer.py failed
STDOUT:
STDERR:Traceback (most recent call last):
  File "/opt/***/scripts/processor_harmonizer.py", line 103, in <module>
    update_files_from_hse_similarity()
  File "/opt/***/scripts/processor_harmonizer.py", line 39, in update_files_from_hse_similarity
    ref_by_country = {k: v.copy() for k, v in ref.groupby(country_col)}
                                              ^^^^^^^^^^^^^^^^^^^^^^^^
  File "/home/***/.local/lib/python3.11/site-packages/pandas/core/frame.py", line 8869, in groupby
    return DataFrameGroupBy(
           ^^^^^^^^^^^^^^^^^
  File "/home/***/.local/lib/python3.11/site-packages/pandas/core/groupby/groupby.py", line 1278, in __init__
    grouper, exclusions, obj = get_grouper(
                               ^^^^^^^^^^^^
  File "/home/***/.local/lib/python3.11/site-packages/pandas/core/groupby/grouper.py", line 1009, in get_grouper
    raise KeyError(gpr)
KeyError: 'Code du pays'
; 306)
[2025-10-05T20:27:16.373+0000] {local_task_job_runner.py:234} INFO - Task exited with return code 1
[2025-10-05T20:27:16.402+0000] {taskinstance.py:3280} INFO - 0 downstream tasks scheduled from follow-on schedule check
