[2025-10-09T18:38:08.383+0000] {taskinstance.py:1956} INFO - Dependencies all met for dep_context=non-requeueable deps ti=<TaskInstance: etl_pipeline_scd2.load_to_dw_scd2 manual__2025-10-09T18:35:13.117084+00:00 [queued]>
[2025-10-09T18:38:08.444+0000] {taskinstance.py:1956} INFO - Dependencies all met for dep_context=requeueable deps ti=<TaskInstance: etl_pipeline_scd2.load_to_dw_scd2 manual__2025-10-09T18:35:13.117084+00:00 [queued]>
[2025-10-09T18:38:08.446+0000] {taskinstance.py:2170} INFO - Starting attempt 1 of 1
[2025-10-09T18:38:08.537+0000] {taskinstance.py:2191} INFO - Executing <Task(PythonOperator): load_to_dw_scd2> on 2025-10-09 18:35:13.117084+00:00
[2025-10-09T18:38:08.569+0000] {standard_task_runner.py:60} INFO - Started process 713 to run task
[2025-10-09T18:38:08.590+0000] {standard_task_runner.py:87} INFO - Running: ['***', 'tasks', 'run', 'etl_pipeline_scd2', 'load_to_dw_scd2', 'manual__2025-10-09T18:35:13.117084+00:00', '--job-id', '344', '--raw', '--subdir', 'DAGS_FOLDER/process_scripts.py', '--cfg-path', '/tmp/tmpols9n81z']
[2025-10-09T18:38:08.616+0000] {standard_task_runner.py:88} INFO - Job 344: Subtask load_to_dw_scd2
[2025-10-09T18:38:08.708+0000] {logging_mixin.py:188} WARNING - /home/***/.local/lib/python3.11/site-packages/***/settings.py:194 DeprecationWarning: The sql_alchemy_conn option in [core] has been moved to the sql_alchemy_conn option in [database] - the old setting has been used, but please update your config.
[2025-10-09T18:38:08.850+0000] {task_command.py:423} INFO - Running <TaskInstance: etl_pipeline_scd2.load_to_dw_scd2 manual__2025-10-09T18:35:13.117084+00:00 [running]> on host 0ccfb9f9695b
[2025-10-09T18:38:09.181+0000] {taskinstance.py:2480} INFO - Exporting env vars: AIRFLOW_CTX_DAG_OWNER='***' AIRFLOW_CTX_DAG_ID='etl_pipeline_scd2' AIRFLOW_CTX_TASK_ID='load_to_dw_scd2' AIRFLOW_CTX_EXECUTION_DATE='2025-10-09T18:35:13.117084+00:00' AIRFLOW_CTX_TRY_NUMBER='1' AIRFLOW_CTX_DAG_RUN_ID='manual__2025-10-09T18:35:13.117084+00:00'
[2025-10-09T18:38:11.942+0000] {scd2_loader.py:257} INFO - ðŸ“‚ Traitement dynamique du fichier: Extract_Station_20251009.xlsx pour map_key=extract_station
[2025-10-09T18:38:18.704+0000] {scd2_loader.py:285} WARNING - 404 lignes ignorÃ©es (clÃ©s manquantes) dans Extract_Station_20251009.xlsx::Sheet1
[2025-10-09T18:38:18.753+0000] {scd2_loader.py:149} INFO - ðŸ”‘ Pour dim_stations on utilise la clÃ© calculÃ©e 'uniq_business'
[2025-10-09T18:38:18.767+0000] {scd2_loader.py:156} WARNING - 633 lignes ignorÃ©es dans dim_stations (clÃ©s manquantes ou doublons)
[2025-10-09T18:38:23.349+0000] {taskinstance.py:2698} ERROR - Task failed with exception
Traceback (most recent call last):
  File "/home/airflow/.local/lib/python3.11/site-packages/sqlalchemy/engine/base.py", line 1890, in _execute_context
    self.dialect.do_executemany(
  File "/home/airflow/.local/lib/python3.11/site-packages/sqlalchemy/dialects/mysql/mysqldb.py", line 183, in do_executemany
    rowcount = cursor.executemany(statement, parameters)
               ^^^^^^^^^^^^^^^^^^^^^^^^^^^^^^^^^^^^^^^^^
  File "/home/airflow/.local/lib/python3.11/site-packages/MySQLdb/cursors.py", line 241, in executemany
    return self._do_execute_many(
           ^^^^^^^^^^^^^^^^^^^^^^
  File "/home/airflow/.local/lib/python3.11/site-packages/MySQLdb/cursors.py", line 275, in _do_execute_many
    rows += self.execute(sql + postfix)
            ^^^^^^^^^^^^^^^^^^^^^^^^^^^
  File "/home/airflow/.local/lib/python3.11/site-packages/MySQLdb/cursors.py", line 179, in execute
    res = self._query(mogrified_query)
          ^^^^^^^^^^^^^^^^^^^^^^^^^^^^
  File "/home/airflow/.local/lib/python3.11/site-packages/MySQLdb/cursors.py", line 330, in _query
    db.query(q)
  File "/home/airflow/.local/lib/python3.11/site-packages/MySQLdb/connections.py", line 257, in query
    _mysql.connection.query(self, query)
MySQLdb.OperationalError: (1054, "Unknown column 'norm_name' in 'field list'")

The above exception was the direct cause of the following exception:

Traceback (most recent call last):
  File "/home/airflow/.local/lib/python3.11/site-packages/airflow/models/taskinstance.py", line 433, in _execute_task
    result = execute_callable(context=context, **execute_callable_kwargs)
             ^^^^^^^^^^^^^^^^^^^^^^^^^^^^^^^^^^^^^^^^^^^^^^^^^^^^^^^^^^^^
  File "/home/airflow/.local/lib/python3.11/site-packages/airflow/operators/python.py", line 199, in execute
    return_value = self.execute_callable()
                   ^^^^^^^^^^^^^^^^^^^^^^^
  File "/home/airflow/.local/lib/python3.11/site-packages/airflow/operators/python.py", line 216, in execute_callable
    return self.python_callable(*self.op_args, **self.op_kwargs)
           ^^^^^^^^^^^^^^^^^^^^^^^^^^^^^^^^^^^^^^^^^^^^^^^^^^^^^
  File "/opt/airflow/dags/process_scripts.py", line 28, in run_scd2_loader
    load_all_out_files_to_dw()
  File "/opt/airflow/dags/scd2_loader.py", line 287, in load_all_out_files_to_dw
    ins, upd = _process_table_batch(engine, table_name, df, business_keys, now)
               ^^^^^^^^^^^^^^^^^^^^^^^^^^^^^^^^^^^^^^^^^^^^^^^^^^^^^^^^^^^^^^^^
  File "/opt/airflow/dags/scd2_loader.py", line 214, in _process_table_batch
    conn.execute(insert_sql, chunk)
  File "/home/airflow/.local/lib/python3.11/site-packages/sqlalchemy/engine/base.py", line 1385, in execute
    return meth(self, multiparams, params, _EMPTY_EXECUTION_OPTS)
           ^^^^^^^^^^^^^^^^^^^^^^^^^^^^^^^^^^^^^^^^^^^^^^^^^^^^^^
  File "/home/airflow/.local/lib/python3.11/site-packages/sqlalchemy/sql/elements.py", line 334, in _execute_on_connection
    return connection._execute_clauseelement(
           ^^^^^^^^^^^^^^^^^^^^^^^^^^^^^^^^^^
  File "/home/airflow/.local/lib/python3.11/site-packages/sqlalchemy/engine/base.py", line 1577, in _execute_clauseelement
    ret = self._execute_context(
          ^^^^^^^^^^^^^^^^^^^^^^
  File "/home/airflow/.local/lib/python3.11/site-packages/sqlalchemy/engine/base.py", line 1953, in _execute_context
    self._handle_dbapi_exception(
  File "/home/airflow/.local/lib/python3.11/site-packages/sqlalchemy/engine/base.py", line 2134, in _handle_dbapi_exception
    util.raise_(
  File "/home/airflow/.local/lib/python3.11/site-packages/sqlalchemy/util/compat.py", line 211, in raise_
    raise exception
  File "/home/airflow/.local/lib/python3.11/site-packages/sqlalchemy/engine/base.py", line 1890, in _execute_context
    self.dialect.do_executemany(
  File "/home/airflow/.local/lib/python3.11/site-packages/sqlalchemy/dialects/mysql/mysqldb.py", line 183, in do_executemany
    rowcount = cursor.executemany(statement, parameters)
               ^^^^^^^^^^^^^^^^^^^^^^^^^^^^^^^^^^^^^^^^^
  File "/home/airflow/.local/lib/python3.11/site-packages/MySQLdb/cursors.py", line 241, in executemany
    return self._do_execute_many(
           ^^^^^^^^^^^^^^^^^^^^^^
  File "/home/airflow/.local/lib/python3.11/site-packages/MySQLdb/cursors.py", line 275, in _do_execute_many
    rows += self.execute(sql + postfix)
            ^^^^^^^^^^^^^^^^^^^^^^^^^^^
  File "/home/airflow/.local/lib/python3.11/site-packages/MySQLdb/cursors.py", line 179, in execute
    res = self._query(mogrified_query)
          ^^^^^^^^^^^^^^^^^^^^^^^^^^^^
  File "/home/airflow/.local/lib/python3.11/site-packages/MySQLdb/cursors.py", line 330, in _query
    db.query(q)
  File "/home/airflow/.local/lib/python3.11/site-packages/MySQLdb/connections.py", line 257, in query
    _mysql.connection.query(self, query)
sqlalchemy.exc.OperationalError: (MySQLdb.OperationalError) (1054, "Unknown column 'norm_name' in 'field list'")
[SQL: INSERT INTO `dim_stations` (`cost_center`, `station_name`, `city`, `segmentation`, `management_method`, `country_code`, `norm_name`, `uniq_business`, `is_current`, `start_date`) VALUES (%s, %s, %s, %s, %s, %s, %s, %s, %s, %s)]
[parameters: (('NG111S0307', 'DOKA CRS SS', 'KADUNA', 'S1', 'CODO', 'NG', 'doka crs ss', 'NG_NG111S0307', 1, datetime.datetime(2025, 10, 9, 18, 38, 11, 902028, tzinfo=datetime.timezone.utc)), ('NG111S0313', 'SOUTH BRIDGE', 'KADUNA', 'S1', 'CODO', 'NG', 'south bridge', 'NG_NG111S0313', 1, datetime.datetime(2025, 10, 9, 18, 38, 11, 902028, tzinfo=datetime.timezone.utc)), ('NG111S0206', 'RUMUOBIAKANI', 'PHC', 'S1', 'CODO', 'NG', 'rumuobiakani', 'NG_NG111S0206', 1, datetime.datetime(2025, 10, 9, 18, 38, 11, 902028, tzinfo=datetime.timezone.utc)), ('NG111S0263', 'JS TARKA', 'ABUJA 1', 'S1', 'CODO', 'NG', 'js tarka', 'NG_NG111S0263', 1, datetime.datetime(2025, 10, 9, 18, 38, 11, 902028, tzinfo=datetime.timezone.utc)), ('NG111S0268', 'SULTAN ABUBAKAR', 'ABUJA 2', 'S1', 'CODO', 'NG', 'sultan abubakar', 'NG_NG111S0268', 1, datetime.datetime(2025, 10, 9, 18, 38, 11, 902028, tzinfo=datetime.timezone.utc)), ('NG111S0271', 'WUSE 1', 'ABUJA 2', 'S1', 'CODO', 'NG', 'wuse 1', 'NG_NG111S0271', 1, datetime.datetime(2025, 10, 9, 18, 38, 11, 902028, tzinfo=datetime.timezone.utc)), ('NG111S0571', 'TIPPER GARAGE S/S', 'ABUJA 3', 'S2', 'CODO', 'NG', 'tipper garage s s', 'NG_NG111S0571', 1, datetime.datetime(2025, 10, 9, 18, 38, 11, 902028, tzinfo=datetime.timezone.utc)), ('NG111S0159', 'CALABAR RD SS', 'CALABAR', 'S1', 'CODO', 'NG', 'calabar rd ss', 'NG_NG111S0159', 1, datetime.datetime(2025, 10, 9, 18, 38, 11, 902028, tzinfo=datetime.timezone.utc))  ... displaying 10 of 500 total bound parameter sets ...  ('112638', '10th Ramadan', None, 'S1', 'CODO', 'EG', '10th ramadan', 'EG_112638', 1, datetime.datetime(2025, 10, 9, 18, 38, 11, 902028, tzinfo=datetime.timezone.utc)), ('117948', '15th May service station city', None, 'S1', 'DODO', 'EG', '15th may service station city', 'EG_117948', 1, datetime.datetime(2025, 10, 9, 18, 38, 11, 902028, tzinfo=datetime.timezone.utc)))]
(Background on this error at: https://sqlalche.me/e/14/e3q8)
[2025-10-09T18:38:23.402+0000] {taskinstance.py:1138} INFO - Marking task as FAILED. dag_id=etl_pipeline_scd2, task_id=load_to_dw_scd2, execution_date=20251009T183513, start_date=20251009T183808, end_date=20251009T183823
[2025-10-09T18:38:23.449+0000] {standard_task_runner.py:107} ERROR - Failed to execute job 344 for task load_to_dw_scd2 ((MySQLdb.OperationalError) (1054, "Unknown column 'norm_name' in 'field list'")
[SQL: INSERT INTO `dim_stations` (`cost_center`, `station_name`, `city`, `segmentation`, `management_method`, `country_code`, `norm_name`, `uniq_business`, `is_current`, `start_date`) VALUES (%s, %s, %s, %s, %s, %s, %s, %s, %s, %s)]
[parameters: (('NG111S0307', 'DOKA CRS SS', 'KADUNA', 'S1', 'CODO', 'NG', 'doka crs ss', 'NG_NG111S0307', 1, datetime.datetime(2025, 10, 9, 18, 38, 11, 902028, tzinfo=datetime.timezone.utc)), ('NG111S0313', 'SOUTH BRIDGE', 'KADUNA', 'S1', 'CODO', 'NG', 'south bridge', 'NG_NG111S0313', 1, datetime.datetime(2025, 10, 9, 18, 38, 11, 902028, tzinfo=datetime.timezone.utc)), ('NG111S0206', 'RUMUOBIAKANI', 'PHC', 'S1', 'CODO', 'NG', 'rumuobiakani', 'NG_NG111S0206', 1, datetime.datetime(2025, 10, 9, 18, 38, 11, 902028, tzinfo=datetime.timezone.utc)), ('NG111S0263', 'JS TARKA', 'ABUJA 1', 'S1', 'CODO', 'NG', 'js tarka', 'NG_NG111S0263', 1, datetime.datetime(2025, 10, 9, 18, 38, 11, 902028, tzinfo=datetime.timezone.utc)), ('NG111S0268', 'SULTAN ABUBAKAR', 'ABUJA 2', 'S1', 'CODO', 'NG', 'sultan abubakar', 'NG_NG111S0268', 1, datetime.datetime(2025, 10, 9, 18, 38, 11, 902028, tzinfo=datetime.timezone.utc)), ('NG111S0271', 'WUSE 1', 'ABUJA 2', 'S1', 'CODO', 'NG', 'wuse 1', 'NG_NG111S0271', 1, datetime.datetime(2025, 10, 9, 18, 38, 11, 902028, tzinfo=datetime.timezone.utc)), ('NG111S0571', 'TIPPER GARAGE S/S', 'ABUJA 3', 'S2', 'CODO', 'NG', 'tipper garage s s', 'NG_NG111S0571', 1, datetime.datetime(2025, 10, 9, 18, 38, 11, 902028, tzinfo=datetime.timezone.utc)), ('NG111S0159', 'CALABAR RD SS', 'CALABAR', 'S1', 'CODO', 'NG', 'calabar rd ss', 'NG_NG111S0159', 1, datetime.datetime(2025, 10, 9, 18, 38, 11, 902028, tzinfo=datetime.timezone.utc))  ... displaying 10 of 500 total bound parameter sets ...  ('112638', '10th Ramadan', None, 'S1', 'CODO', 'EG', '10th ramadan', 'EG_112638', 1, datetime.datetime(2025, 10, 9, 18, 38, 11, 902028, tzinfo=datetime.timezone.utc)), ('117948', '15th May service station city', None, 'S1', 'DODO', 'EG', '15th may service station city', 'EG_117948', 1, datetime.datetime(2025, 10, 9, 18, 38, 11, 902028, tzinfo=datetime.timezone.utc)))]
(Background on this error at: https://sqlalche.me/e/14/e3q8); 713)
[2025-10-09T18:38:23.497+0000] {local_task_job_runner.py:234} INFO - Task exited with return code 1
[2025-10-09T18:38:23.548+0000] {taskinstance.py:3280} INFO - 0 downstream tasks scheduled from follow-on schedule check
