[2025-10-06T16:01:30.813+0000] {taskinstance.py:1956} INFO - Dependencies all met for dep_context=non-requeueable deps ti=<TaskInstance: etl_pipeline_scd2.run_processor_harmonizer manual__2025-10-06T15:59:57.627110+00:00 [queued]>
[2025-10-06T16:01:30.831+0000] {taskinstance.py:1956} INFO - Dependencies all met for dep_context=requeueable deps ti=<TaskInstance: etl_pipeline_scd2.run_processor_harmonizer manual__2025-10-06T15:59:57.627110+00:00 [queued]>
[2025-10-06T16:01:30.834+0000] {taskinstance.py:2170} INFO - Starting attempt 1 of 1
[2025-10-06T16:01:30.891+0000] {taskinstance.py:2191} INFO - Executing <Task(PythonOperator): run_processor_harmonizer> on 2025-10-06 15:59:57.627110+00:00
[2025-10-06T16:01:30.906+0000] {standard_task_runner.py:60} INFO - Started process 1849 to run task
[2025-10-06T16:01:30.922+0000] {standard_task_runner.py:87} INFO - Running: ['***', 'tasks', 'run', 'etl_pipeline_scd2', 'run_processor_harmonizer', 'manual__2025-10-06T15:59:57.627110+00:00', '--job-id', '192', '--raw', '--subdir', 'DAGS_FOLDER/process_scripts.py', '--cfg-path', '/tmp/tmp4hlu6b0a']
[2025-10-06T16:01:30.932+0000] {standard_task_runner.py:88} INFO - Job 192: Subtask run_processor_harmonizer
[2025-10-06T16:01:31.013+0000] {logging_mixin.py:188} WARNING - /home/***/.local/lib/python3.11/site-packages/***/settings.py:194 DeprecationWarning: The sql_alchemy_conn option in [core] has been moved to the sql_alchemy_conn option in [database] - the old setting has been used, but please update your config.
[2025-10-06T16:01:31.143+0000] {task_command.py:423} INFO - Running <TaskInstance: etl_pipeline_scd2.run_processor_harmonizer manual__2025-10-06T15:59:57.627110+00:00 [running]> on host 548a0c322259
[2025-10-06T16:01:31.291+0000] {taskinstance.py:2480} INFO - Exporting env vars: AIRFLOW_CTX_DAG_OWNER='***' AIRFLOW_CTX_DAG_ID='etl_pipeline_scd2' AIRFLOW_CTX_TASK_ID='run_processor_harmonizer' AIRFLOW_CTX_EXECUTION_DATE='2025-10-06T15:59:57.627110+00:00' AIRFLOW_CTX_TRY_NUMBER='1' AIRFLOW_CTX_DAG_RUN_ID='manual__2025-10-06T15:59:57.627110+00:00'
[2025-10-06T16:02:31.259+0000] {taskinstance.py:2698} ERROR - Task failed with exception
Traceback (most recent call last):
  File "/home/airflow/.local/lib/python3.11/site-packages/airflow/models/taskinstance.py", line 433, in _execute_task
    result = execute_callable(context=context, **execute_callable_kwargs)
             ^^^^^^^^^^^^^^^^^^^^^^^^^^^^^^^^^^^^^^^^^^^^^^^^^^^^^^^^^^^^
  File "/home/airflow/.local/lib/python3.11/site-packages/airflow/operators/python.py", line 199, in execute
    return_value = self.execute_callable()
                   ^^^^^^^^^^^^^^^^^^^^^^^
  File "/home/airflow/.local/lib/python3.11/site-packages/airflow/operators/python.py", line 216, in execute_callable
    return self.python_callable(*self.op_args, **self.op_kwargs)
           ^^^^^^^^^^^^^^^^^^^^^^^^^^^^^^^^^^^^^^^^^^^^^^^^^^^^^
  File "/opt/airflow/dags/process_scripts.py", line 20, in run_script
    raise Exception(f"Script {script_path} failed\nSTDOUT:{result.stdout}\nSTDERR:{result.stderr}")
Exception: Script /opt/***/scripts/processor_harmonizer.py failed
STDOUT:⚠ Ignoré (colonnes manquantes) : Country_code.xlsx
✅ 280/5202 lignes mises à jour dans Extract_Station.xlsx

STDERR:Traceback (most recent call last):
  File "/home/***/.local/lib/python3.11/site-packages/pandas/core/indexes/base.py", line 3791, in get_loc
    return self._engine.get_loc(casted_key)
           ^^^^^^^^^^^^^^^^^^^^^^^^^^^^^^^^
  File "index.pyx", line 152, in pandas._libs.index.IndexEngine.get_loc
  File "index.pyx", line 181, in pandas._libs.index.IndexEngine.get_loc
  File "pandas/_libs/hashtable_class_helper.pxi", line 7080, in pandas._libs.hashtable.PyObjectHashTable.get_item
  File "pandas/_libs/hashtable_class_helper.pxi", line 7088, in pandas._libs.hashtable.PyObjectHashTable.get_item
KeyError: 'Station code'

The above exception was the direct cause of the following exception:

Traceback (most recent call last):
  File "/opt/***/scripts/processor_harmonizer.py", line 155, in <module>
    update_all_in_out()
  File "/opt/***/scripts/processor_harmonizer.py", line 150, in update_all_in_out
    update_file(ref, file_path, updated_dir, backup_dir, score_threshold=score_threshold)
  File "/opt/***/scripts/processor_harmonizer.py", line 87, in update_file
    matches = matches[matches["Station code"] == row.get(cost_col, "")]
                      ~~~~~~~^^^^^^^^^^^^^^^^
  File "/home/***/.local/lib/python3.11/site-packages/pandas/core/frame.py", line 3893, in __getitem__
    indexer = self.columns.get_loc(key)
              ^^^^^^^^^^^^^^^^^^^^^^^^^
  File "/home/***/.local/lib/python3.11/site-packages/pandas/core/indexes/base.py", line 3798, in get_loc
    raise KeyError(key) from err
KeyError: 'Station code'

[2025-10-06T16:02:31.615+0000] {taskinstance.py:1138} INFO - Marking task as FAILED. dag_id=etl_pipeline_scd2, task_id=run_processor_harmonizer, execution_date=20251006T155957, start_date=20251006T160130, end_date=20251006T160231
[2025-10-06T16:02:31.888+0000] {standard_task_runner.py:107} ERROR - Failed to execute job 192 for task run_processor_harmonizer (Script /opt/***/scripts/processor_harmonizer.py failed
STDOUT:⚠ Ignoré (colonnes manquantes) : Country_code.xlsx
✅ 280/5202 lignes mises à jour dans Extract_Station.xlsx

STDERR:Traceback (most recent call last):
  File "/home/***/.local/lib/python3.11/site-packages/pandas/core/indexes/base.py", line 3791, in get_loc
    return self._engine.get_loc(casted_key)
           ^^^^^^^^^^^^^^^^^^^^^^^^^^^^^^^^
  File "index.pyx", line 152, in pandas._libs.index.IndexEngine.get_loc
  File "index.pyx", line 181, in pandas._libs.index.IndexEngine.get_loc
  File "pandas/_libs/hashtable_class_helper.pxi", line 7080, in pandas._libs.hashtable.PyObjectHashTable.get_item
  File "pandas/_libs/hashtable_class_helper.pxi", line 7088, in pandas._libs.hashtable.PyObjectHashTable.get_item
KeyError: 'Station code'

The above exception was the direct cause of the following exception:

Traceback (most recent call last):
  File "/opt/***/scripts/processor_harmonizer.py", line 155, in <module>
    update_all_in_out()
  File "/opt/***/scripts/processor_harmonizer.py", line 150, in update_all_in_out
    update_file(ref, file_path, updated_dir, backup_dir, score_threshold=score_threshold)
  File "/opt/***/scripts/processor_harmonizer.py", line 87, in update_file
    matches = matches[matches["Station code"] == row.get(cost_col, "")]
                      ~~~~~~~^^^^^^^^^^^^^^^^
  File "/home/***/.local/lib/python3.11/site-packages/pandas/core/frame.py", line 3893, in __getitem__
    indexer = self.columns.get_loc(key)
              ^^^^^^^^^^^^^^^^^^^^^^^^^
  File "/home/***/.local/lib/python3.11/site-packages/pandas/core/indexes/base.py", line 3798, in get_loc
    raise KeyError(key) from err
KeyError: 'Station code'
; 1849)
[2025-10-06T16:02:32.072+0000] {local_task_job_runner.py:234} INFO - Task exited with return code 1
[2025-10-06T16:02:32.319+0000] {taskinstance.py:3280} INFO - 0 downstream tasks scheduled from follow-on schedule check
