[2025-10-09T18:10:28.721+0000] {taskinstance.py:1956} INFO - Dependencies all met for dep_context=non-requeueable deps ti=<TaskInstance: etl_pipeline_scd2.ERIS_Report_Extraction_31_07_2025_processor_extract_HSE manual__2025-10-09T18:10:24.821540+00:00 [queued]>
[2025-10-09T18:10:28.753+0000] {taskinstance.py:1956} INFO - Dependencies all met for dep_context=requeueable deps ti=<TaskInstance: etl_pipeline_scd2.ERIS_Report_Extraction_31_07_2025_processor_extract_HSE manual__2025-10-09T18:10:24.821540+00:00 [queued]>
[2025-10-09T18:10:28.756+0000] {taskinstance.py:2170} INFO - Starting attempt 1 of 1
[2025-10-09T18:10:28.815+0000] {taskinstance.py:2191} INFO - Executing <Task(PythonOperator): ERIS_Report_Extraction_31_07_2025_processor_extract_HSE> on 2025-10-09 18:10:24.821540+00:00
[2025-10-09T18:10:28.849+0000] {standard_task_runner.py:60} INFO - Started process 234 to run task
[2025-10-09T18:10:28.861+0000] {standard_task_runner.py:87} INFO - Running: ['***', 'tasks', 'run', 'etl_pipeline_scd2', 'ERIS_Report_Extraction_31_07_2025_processor_extract_HSE', 'manual__2025-10-09T18:10:24.821540+00:00', '--job-id', '329', '--raw', '--subdir', 'DAGS_FOLDER/process_scripts.py', '--cfg-path', '/tmp/tmpmskqjv_s']
[2025-10-09T18:10:28.871+0000] {standard_task_runner.py:88} INFO - Job 329: Subtask ERIS_Report_Extraction_31_07_2025_processor_extract_HSE
[2025-10-09T18:10:28.940+0000] {logging_mixin.py:188} WARNING - /home/***/.local/lib/python3.11/site-packages/***/settings.py:194 DeprecationWarning: The sql_alchemy_conn option in [core] has been moved to the sql_alchemy_conn option in [database] - the old setting has been used, but please update your config.
[2025-10-09T18:10:29.113+0000] {task_command.py:423} INFO - Running <TaskInstance: etl_pipeline_scd2.ERIS_Report_Extraction_31_07_2025_processor_extract_HSE manual__2025-10-09T18:10:24.821540+00:00 [running]> on host 0ccfb9f9695b
[2025-10-09T18:10:29.338+0000] {taskinstance.py:2480} INFO - Exporting env vars: AIRFLOW_CTX_DAG_OWNER='***' AIRFLOW_CTX_DAG_ID='etl_pipeline_scd2' AIRFLOW_CTX_TASK_ID='ERIS_Report_Extraction_31_07_2025_processor_extract_HSE' AIRFLOW_CTX_EXECUTION_DATE='2025-10-09T18:10:24.821540+00:00' AIRFLOW_CTX_TRY_NUMBER='1' AIRFLOW_CTX_DAG_RUN_ID='manual__2025-10-09T18:10:24.821540+00:00'
[2025-10-09T18:10:34.879+0000] {taskinstance.py:2698} ERROR - Task failed with exception
Traceback (most recent call last):
  File "/home/airflow/.local/lib/python3.11/site-packages/airflow/models/taskinstance.py", line 433, in _execute_task
    result = execute_callable(context=context, **execute_callable_kwargs)
             ^^^^^^^^^^^^^^^^^^^^^^^^^^^^^^^^^^^^^^^^^^^^^^^^^^^^^^^^^^^^
  File "/home/airflow/.local/lib/python3.11/site-packages/airflow/operators/python.py", line 199, in execute
    return_value = self.execute_callable()
                   ^^^^^^^^^^^^^^^^^^^^^^^
  File "/home/airflow/.local/lib/python3.11/site-packages/airflow/operators/python.py", line 216, in execute_callable
    return self.python_callable(*self.op_args, **self.op_kwargs)
           ^^^^^^^^^^^^^^^^^^^^^^^^^^^^^^^^^^^^^^^^^^^^^^^^^^^^^
  File "/opt/airflow/dags/process_scripts.py", line 29, in run_script
    raise Exception(f"Script {script_path} failed\nSTDOUT:{result.stdout}\nSTDERR:{result.stderr}")
Exception: Script /opt/***/scripts/processor_extract_HSE.py failed
STDOUT:
STDERR:Traceback (most recent call last):
  File "/opt/***/scripts/processor_extract_HSE.py", line 140, in <module>
    result = extract_hse_invariants(
             ^^^^^^^^^^^^^^^^^^^^^^^
  File "/opt/***/scripts/processor_extract_HSE.py", line 106, in extract_hse_invariants
    raise FileNotFoundError("Aucun fichier contenant 'extraction' trouvé dans le répertoire input.")
FileNotFoundError: Aucun fichier contenant 'extraction' trouvé dans le répertoire input.

[2025-10-09T18:10:34.920+0000] {taskinstance.py:1138} INFO - Marking task as FAILED. dag_id=etl_pipeline_scd2, task_id=ERIS_Report_Extraction_31_07_2025_processor_extract_HSE, execution_date=20251009T181024, start_date=20251009T181028, end_date=20251009T181034
[2025-10-09T18:10:34.979+0000] {standard_task_runner.py:107} ERROR - Failed to execute job 329 for task ERIS_Report_Extraction_31_07_2025_processor_extract_HSE (Script /opt/***/scripts/processor_extract_HSE.py failed
STDOUT:
STDERR:Traceback (most recent call last):
  File "/opt/***/scripts/processor_extract_HSE.py", line 140, in <module>
    result = extract_hse_invariants(
             ^^^^^^^^^^^^^^^^^^^^^^^
  File "/opt/***/scripts/processor_extract_HSE.py", line 106, in extract_hse_invariants
    raise FileNotFoundError("Aucun fichier contenant 'extraction' trouvé dans le répertoire input.")
FileNotFoundError: Aucun fichier contenant 'extraction' trouvé dans le répertoire input.
; 234)
[2025-10-09T18:10:35.037+0000] {local_task_job_runner.py:234} INFO - Task exited with return code 1
[2025-10-09T18:10:35.091+0000] {taskinstance.py:3280} INFO - 0 downstream tasks scheduled from follow-on schedule check
