[2025-10-24T01:49:54.960+0000] {taskinstance.py:1956} INFO - Dependencies all met for dep_context=non-requeueable deps ti=<TaskInstance: etl_pipeline_scd2.load_to_dw_scd2 manual__2025-10-24T01:44:15.275792+00:00 [queued]>
[2025-10-24T01:49:54.982+0000] {taskinstance.py:1956} INFO - Dependencies all met for dep_context=requeueable deps ti=<TaskInstance: etl_pipeline_scd2.load_to_dw_scd2 manual__2025-10-24T01:44:15.275792+00:00 [queued]>
[2025-10-24T01:49:54.984+0000] {taskinstance.py:2170} INFO - Starting attempt 1 of 1
[2025-10-24T01:49:55.022+0000] {taskinstance.py:2191} INFO - Executing <Task(PythonOperator): load_to_dw_scd2> on 2025-10-24 01:44:15.275792+00:00
[2025-10-24T01:49:55.041+0000] {standard_task_runner.py:60} INFO - Started process 4946 to run task
[2025-10-24T01:49:55.077+0000] {standard_task_runner.py:87} INFO - Running: ['***', 'tasks', 'run', 'etl_pipeline_scd2', 'load_to_dw_scd2', 'manual__2025-10-24T01:44:15.275792+00:00', '--job-id', '238', '--raw', '--subdir', 'DAGS_FOLDER/process_scripts.py', '--cfg-path', '/tmp/tmpnvgmh763']
[2025-10-24T01:49:55.109+0000] {standard_task_runner.py:88} INFO - Job 238: Subtask load_to_dw_scd2
[2025-10-24T01:49:55.204+0000] {logging_mixin.py:188} WARNING - /home/***/.local/lib/python3.11/site-packages/***/settings.py:194 DeprecationWarning: The sql_alchemy_conn option in [core] has been moved to the sql_alchemy_conn option in [database] - the old setting has been used, but please update your config.
[2025-10-24T01:49:55.364+0000] {task_command.py:423} INFO - Running <TaskInstance: etl_pipeline_scd2.load_to_dw_scd2 manual__2025-10-24T01:44:15.275792+00:00 [running]> on host ca755dafa923
[2025-10-24T01:49:55.669+0000] {taskinstance.py:2480} INFO - Exporting env vars: AIRFLOW_CTX_DAG_OWNER='***' AIRFLOW_CTX_DAG_ID='etl_pipeline_scd2' AIRFLOW_CTX_TASK_ID='load_to_dw_scd2' AIRFLOW_CTX_EXECUTION_DATE='2025-10-24T01:44:15.275792+00:00' AIRFLOW_CTX_TRY_NUMBER='1' AIRFLOW_CTX_DAG_RUN_ID='manual__2025-10-24T01:44:15.275792+00:00'
[2025-10-24T01:49:58.673+0000] {scd2_loader.py:301} INFO - Traitement dynamique du fichier: Country_code_20251024.xlsx pour map_key=country_code
[2025-10-24T01:49:59.688+0000] {scd2_loader.py:349} WARNING - 1 lignes ignorées (clés manquantes) dans Country_code_20251024.xlsx::Sheet1
[2025-10-24T01:49:59.926+0000] {scd2_loader.py:271} INFO - [SCD2] dim_pays → inserts=0, updates_closed=0
[2025-10-24T01:49:59.927+0000] {scd2_loader.py:301} INFO - Traitement dynamique du fichier: Extract_Station_20251024.xlsx pour map_key=extract_station
[2025-10-24T01:50:01.561+0000] {scd2_loader.py:349} WARNING - 2 lignes ignorées (clés manquantes) dans Extract_Station_20251024.xlsx::Sheet1
[2025-10-24T01:50:01.604+0000] {scd2_loader.py:179} INFO - Pour dim_stations on utilise la clé calculée 'uniq_business'
[2025-10-24T01:50:01.613+0000] {scd2_loader.py:186} WARNING - 739 lignes ignorées dans dim_stations (clés manquantes ou doublons)
[2025-10-24T01:50:03.919+0000] {scd2_loader.py:271} INFO - [SCD2] dim_stations → inserts=0, updates_closed=0
[2025-10-24T01:50:03.926+0000] {scd2_loader.py:301} INFO - Traitement dynamique du fichier: Inspections_20250815.xlsx pour map_key=inspections
[2025-10-24T01:50:03.975+0000] {scd2_loader.py:186} WARNING - 71 lignes ignorées dans fact_inspections (clés manquantes ou doublons)
[2025-10-24T01:50:04.074+0000] {scd2_loader.py:271} INFO - [SCD2] fact_inspections → inserts=0, updates_closed=0
[2025-10-24T01:50:04.075+0000] {scd2_loader.py:301} INFO - Traitement dynamique du fichier: Invariants_details_20251024.xlsx pour map_key=invariants_details
[2025-10-24T01:50:15.006+0000] {scd2_loader.py:337} INFO -  Colonne 'status' transformée: Compliant=100, Non compliant=0, N/A=NULL, vide=NULL
[2025-10-24T01:50:15.082+0000] {scd2_loader.py:186} WARNING - 86592 lignes ignorées dans dim_invariants_details (clés manquantes ou doublons)
[2025-10-24T01:50:15.437+0000] {taskinstance.py:2698} ERROR - Task failed with exception
Traceback (most recent call last):
  File "/home/airflow/.local/lib/python3.11/site-packages/sqlalchemy/engine/base.py", line 1890, in _execute_context
    self.dialect.do_executemany(
  File "/home/airflow/.local/lib/python3.11/site-packages/sqlalchemy/dialects/mysql/mysqldb.py", line 183, in do_executemany
    rowcount = cursor.executemany(statement, parameters)
               ^^^^^^^^^^^^^^^^^^^^^^^^^^^^^^^^^^^^^^^^^
  File "/home/airflow/.local/lib/python3.11/site-packages/MySQLdb/cursors.py", line 241, in executemany
    return self._do_execute_many(
           ^^^^^^^^^^^^^^^^^^^^^^
  File "/home/airflow/.local/lib/python3.11/site-packages/MySQLdb/cursors.py", line 268, in _do_execute_many
    v = self._mogrify(values, arg)
        ^^^^^^^^^^^^^^^^^^^^^^^^^^
  File "/home/airflow/.local/lib/python3.11/site-packages/MySQLdb/cursors.py", line 198, in _mogrify
    args = tuple(map(db.literal, args))
           ^^^^^^^^^^^^^^^^^^^^^^^^^^^^
  File "/home/airflow/.local/lib/python3.11/site-packages/MySQLdb/connections.py", line 286, in literal
    s = self.escape(o, self.encoders)
        ^^^^^^^^^^^^^^^^^^^^^^^^^^^^^
  File "/home/airflow/.local/lib/python3.11/site-packages/MySQLdb/converters.py", line 76, in Float2Str
    raise ProgrammingError("%s can not be used with MySQL" % s)
MySQLdb.ProgrammingError: nan can not be used with MySQL

The above exception was the direct cause of the following exception:

Traceback (most recent call last):
  File "/home/airflow/.local/lib/python3.11/site-packages/airflow/models/taskinstance.py", line 433, in _execute_task
    result = execute_callable(context=context, **execute_callable_kwargs)
             ^^^^^^^^^^^^^^^^^^^^^^^^^^^^^^^^^^^^^^^^^^^^^^^^^^^^^^^^^^^^
  File "/home/airflow/.local/lib/python3.11/site-packages/airflow/operators/python.py", line 199, in execute
    return_value = self.execute_callable()
                   ^^^^^^^^^^^^^^^^^^^^^^^
  File "/home/airflow/.local/lib/python3.11/site-packages/airflow/operators/python.py", line 216, in execute_callable
    return self.python_callable(*self.op_args, **self.op_kwargs)
           ^^^^^^^^^^^^^^^^^^^^^^^^^^^^^^^^^^^^^^^^^^^^^^^^^^^^^
  File "/opt/airflow/dags/process_scripts.py", line 52, in run_scd2_loader
    load_all_out_files_to_dw()
  File "/opt/airflow/dags/scd2_loader.py", line 351, in load_all_out_files_to_dw
    ins, upd = _process_table_batch(engine, table_name, df, [_sql_safe_colname(k) for k in business_keys], now)
               ^^^^^^^^^^^^^^^^^^^^^^^^^^^^^^^^^^^^^^^^^^^^^^^^^^^^^^^^^^^^^^^^^^^^^^^^^^^^^^^^^^^^^^^^^^^^^^^^
  File "/opt/airflow/dags/scd2_loader.py", line 258, in _process_table_batch
    conn.execute(insert_sql, chunk)
  File "/home/airflow/.local/lib/python3.11/site-packages/sqlalchemy/engine/base.py", line 1385, in execute
    return meth(self, multiparams, params, _EMPTY_EXECUTION_OPTS)
           ^^^^^^^^^^^^^^^^^^^^^^^^^^^^^^^^^^^^^^^^^^^^^^^^^^^^^^
  File "/home/airflow/.local/lib/python3.11/site-packages/sqlalchemy/sql/elements.py", line 334, in _execute_on_connection
    return connection._execute_clauseelement(
           ^^^^^^^^^^^^^^^^^^^^^^^^^^^^^^^^^^
  File "/home/airflow/.local/lib/python3.11/site-packages/sqlalchemy/engine/base.py", line 1577, in _execute_clauseelement
    ret = self._execute_context(
          ^^^^^^^^^^^^^^^^^^^^^^
  File "/home/airflow/.local/lib/python3.11/site-packages/sqlalchemy/engine/base.py", line 1953, in _execute_context
    self._handle_dbapi_exception(
  File "/home/airflow/.local/lib/python3.11/site-packages/sqlalchemy/engine/base.py", line 2134, in _handle_dbapi_exception
    util.raise_(
  File "/home/airflow/.local/lib/python3.11/site-packages/sqlalchemy/util/compat.py", line 211, in raise_
    raise exception
  File "/home/airflow/.local/lib/python3.11/site-packages/sqlalchemy/engine/base.py", line 1890, in _execute_context
    self.dialect.do_executemany(
  File "/home/airflow/.local/lib/python3.11/site-packages/sqlalchemy/dialects/mysql/mysqldb.py", line 183, in do_executemany
    rowcount = cursor.executemany(statement, parameters)
               ^^^^^^^^^^^^^^^^^^^^^^^^^^^^^^^^^^^^^^^^^
  File "/home/airflow/.local/lib/python3.11/site-packages/MySQLdb/cursors.py", line 241, in executemany
    return self._do_execute_many(
           ^^^^^^^^^^^^^^^^^^^^^^
  File "/home/airflow/.local/lib/python3.11/site-packages/MySQLdb/cursors.py", line 268, in _do_execute_many
    v = self._mogrify(values, arg)
        ^^^^^^^^^^^^^^^^^^^^^^^^^^
  File "/home/airflow/.local/lib/python3.11/site-packages/MySQLdb/cursors.py", line 198, in _mogrify
    args = tuple(map(db.literal, args))
           ^^^^^^^^^^^^^^^^^^^^^^^^^^^^
  File "/home/airflow/.local/lib/python3.11/site-packages/MySQLdb/connections.py", line 286, in literal
    s = self.escape(o, self.encoders)
        ^^^^^^^^^^^^^^^^^^^^^^^^^^^^^
  File "/home/airflow/.local/lib/python3.11/site-packages/MySQLdb/converters.py", line 76, in Float2Str
    raise ProgrammingError("%s can not be used with MySQL" % s)
sqlalchemy.exc.ProgrammingError: (MySQLdb.ProgrammingError) nan can not be used with MySQL
[SQL: INSERT INTO `dim_invariants_details` (`country_code`, `cost_center`, `status`, `year_of_compliance`, `cost_estimate_k_local_currency`, `norm_cost`, `norm_country`, `is_current`, `start_date`) VALUES (%s, %s, %s, %s, %s, %s, %s, %s, %s)]
[parameters: (('YT', 'YT247', 100.0, None, None, '247', 'YT', 1, datetime.datetime(2025, 10, 24, 1, 49, 58, 202191, tzinfo=datetime.timezone.utc)), ('YT', 'YT248', 100.0, None, None, '248', 'YT', 1, datetime.datetime(2025, 10, 24, 1, 49, 58, 202191, tzinfo=datetime.timezone.utc)), ('YT', 'YT249', 100.0, None, None, '249', 'YT', 1, datetime.datetime(2025, 10, 24, 1, 49, 58, 202191, tzinfo=datetime.timezone.utc)), ('YT', 'YT', 100.0, None, None, None, 'YT', 1, datetime.datetime(2025, 10, 24, 1, 49, 58, 202191, tzinfo=datetime.timezone.utc)), ('EG', '112638', 100.0, None, None, '112638', 'EG', 1, datetime.datetime(2025, 10, 24, 1, 49, 58, 202191, tzinfo=datetime.timezone.utc)), ('EG', '117948', 100.0, None, None, '117948', 'EG', 1, datetime.datetime(2025, 10, 24, 1, 49, 58, 202191, tzinfo=datetime.timezone.utc)), ('EG', '105514', 100.0, None, None, '105514', 'EG', 1, datetime.datetime(2025, 10, 24, 1, 49, 58, 202191, tzinfo=datetime.timezone.utc)), ('EG', '107818', 100.0, None, None, '107818', 'EG', 1, datetime.datetime(2025, 10, 24, 1, 49, 58, 202191, tzinfo=datetime.timezone.utc))  ... displaying 10 of 500 total bound parameter sets ...  ('MA', 'MA111S4264', 100.0, None, None, '1114264', 'MA', 1, datetime.datetime(2025, 10, 24, 1, 49, 58, 202191, tzinfo=datetime.timezone.utc)), ('MA', 'MA111S4370', 100.0, None, None, '1114370', 'MA', 1, datetime.datetime(2025, 10, 24, 1, 49, 58, 202191, tzinfo=datetime.timezone.utc)))]
(Background on this error at: https://sqlalche.me/e/14/f405)
[2025-10-24T01:50:15.486+0000] {taskinstance.py:1138} INFO - Marking task as FAILED. dag_id=etl_pipeline_scd2, task_id=load_to_dw_scd2, execution_date=20251024T014415, start_date=20251024T014954, end_date=20251024T015015
[2025-10-24T01:50:15.525+0000] {standard_task_runner.py:107} ERROR - Failed to execute job 238 for task load_to_dw_scd2 ((MySQLdb.ProgrammingError) nan can not be used with MySQL
[SQL: INSERT INTO `dim_invariants_details` (`country_code`, `cost_center`, `status`, `year_of_compliance`, `cost_estimate_k_local_currency`, `norm_cost`, `norm_country`, `is_current`, `start_date`) VALUES (%s, %s, %s, %s, %s, %s, %s, %s, %s)]
[parameters: (('YT', 'YT247', 100.0, None, None, '247', 'YT', 1, datetime.datetime(2025, 10, 24, 1, 49, 58, 202191, tzinfo=datetime.timezone.utc)), ('YT', 'YT248', 100.0, None, None, '248', 'YT', 1, datetime.datetime(2025, 10, 24, 1, 49, 58, 202191, tzinfo=datetime.timezone.utc)), ('YT', 'YT249', 100.0, None, None, '249', 'YT', 1, datetime.datetime(2025, 10, 24, 1, 49, 58, 202191, tzinfo=datetime.timezone.utc)), ('YT', 'YT', 100.0, None, None, None, 'YT', 1, datetime.datetime(2025, 10, 24, 1, 49, 58, 202191, tzinfo=datetime.timezone.utc)), ('EG', '112638', 100.0, None, None, '112638', 'EG', 1, datetime.datetime(2025, 10, 24, 1, 49, 58, 202191, tzinfo=datetime.timezone.utc)), ('EG', '117948', 100.0, None, None, '117948', 'EG', 1, datetime.datetime(2025, 10, 24, 1, 49, 58, 202191, tzinfo=datetime.timezone.utc)), ('EG', '105514', 100.0, None, None, '105514', 'EG', 1, datetime.datetime(2025, 10, 24, 1, 49, 58, 202191, tzinfo=datetime.timezone.utc)), ('EG', '107818', 100.0, None, None, '107818', 'EG', 1, datetime.datetime(2025, 10, 24, 1, 49, 58, 202191, tzinfo=datetime.timezone.utc))  ... displaying 10 of 500 total bound parameter sets ...  ('MA', 'MA111S4264', 100.0, None, None, '1114264', 'MA', 1, datetime.datetime(2025, 10, 24, 1, 49, 58, 202191, tzinfo=datetime.timezone.utc)), ('MA', 'MA111S4370', 100.0, None, None, '1114370', 'MA', 1, datetime.datetime(2025, 10, 24, 1, 49, 58, 202191, tzinfo=datetime.timezone.utc)))]
(Background on this error at: https://sqlalche.me/e/14/f405); 4946)
[2025-10-24T01:50:15.592+0000] {local_task_job_runner.py:234} INFO - Task exited with return code 1
[2025-10-24T01:50:15.631+0000] {taskinstance.py:3280} INFO - 0 downstream tasks scheduled from follow-on schedule check
